Workbook

Sheet 재고표
A1: 재고표 | C1: PL | D1: -0.5 | E1: -0.75 | F1: -1 | G1: -1.25 | H1: -1.5 | I1: -1.75 | J1: -2 | K1: -2.25 | L1: -2.5 | M1: -2.75 | N1: -3 | O1: -3.25 | P1: -3.5 | Q1: -3.75 | R1: -4 | S1: -4.25 | T1: -4.5 | U1: -4.75 | V1: -5 | W1: -5.25 | X1: -5.5 | Y1: -5.75 | Z1: -6 | AA1: -6.5 | AB1: -7 | AC1: -7.5 | AD1: -8 | AE1: -8.5 | AF1: -9 | AG1: -9.5 | AH1: -10 | AI1: -10.5 | AJ1: -11 | AK1: -11.5 | AL1: -12 | BF1: =IF(AND(AN1<30, V1>=30), "증가", "")
A2: *미셀리아 | AO2: =TODAY() -> 46203 | BY2: =TODAY()-1 -> 46202
A3: 1 | B3: 미셀리아 Deep Black | C3: =SUMIF(WMS용마재고!$A:$A,"S174-00.00", WMS용마재고!$L:$L) -> 831 | F3: =SUMIF(WMS용마재고!$A:$A,"S174-01.00", WMS용마재고!$L:$L) -> 588 | G3: =SUMIF(WMS용마재고!$A:$A,"S174-01.25", WMS용마재고!$L:$L) -> 762 | H3: =SUMIF(WMS용마재고!$A:$A,"S174-01.50", WMS용마재고!$L:$L) -> 622 | I3: =SUMIF(WMS용마재고!$A:$A,"S174-01.75", WMS용마재고!$L:$L) -> 599 | J3: =SUMIF(WMS용마재고!$A:$A,"S174-02.00", WMS용마재고!$L:$L) -> 556 | K3: =SUMIF(WMS용마재고!$A:$A,"S174-02.25", WMS용마재고!$L:$L) -> 606 | L3: =SUMIF(WMS용마재고!$A:$A,"S174-02.50", WMS용마재고!$L:$L) -> 1141 | M3: =SUMIF(WMS용마재고!$A:$A,"S174-02.75", WMS용마재고!$L:$L) -> 581 | N3: =SUMIF(WMS용마재고!$A:$A,"S174-03.00", WMS용마재고!$L:$L) -> 605 | O3: =SUMIF(WMS용마재고!$A:$A,"S174-03.25", WMS용마재고!$L:$L) -> 724 | P3: =SUMIF(WMS용마재고!$A:$A,"S174-03.50", WMS용마재고!$L:$L) -> 766 | Q3: =SUMIF(WMS용마재고!$A:$A,"S174-03.75", WMS용마재고!$L:$L) -> 686 | R3: =SUMIF(WMS용마재고!$A:$A,"S174-04.00", WMS용마재고!$L:$L) -> 575 | S3: =SUMIF(WMS용마재고!$A:$A,"S174-04.25", WMS용마재고!$L:$L) -> 584 | T3: =SUMIF(WMS용마재고!$A:$A,"S174-04.50", WMS용마재고!$L:$L) -> 587 | U3: =SUMIF(WMS용마재고!$A:$A,"S174-04.75", WMS용마재고!$L:$L) -> 585 | V3: =SUMIF(WMS용마재고!$A:$A,"S174-05.00", WMS용마재고!$L:$L) -> 593 | X3: =SUMIF(WMS용마재고!$A:$A,"S174-05.50", WMS용마재고!$L:$L) -> 613 | Z3: =SUMIF(WMS용마재고!$A:$A,"S174-06.00", WMS용마재고!$L:$L) -> 616 | AA3: =SUMIF(WMS용마재고!$A:$A,"S174-06.50", WMS용마재고!$L:$L) -> 622 | AB3: =SUMIF(WMS용마재고!$A:$A,"S174-07.00", WMS용마재고!$L:$L) -> 537 | AC3: =SUMIF(WMS용마재고!$A:$A,"S174-07.50", WMS용마재고!$L:$L) -> 670 | AD3: =SUMIF(WMS용마재고!$A:$A,"S174-08.00", WMS용마재고!$L:$L) -> 659 | AN3: O2O2 D_Sepia Choco | AO3: =SUMIF(WMS용마재고!$A:$A,"S174-00.00", WMS용마재고!$L:$L) -> 831 | AP3: =SUMIF(WMS용마재고!$A:$A,"S174-00.50", WMS용마재고!$L:$L) -> 0 | AQ3: =SUMIF(WMS용마재고!$A:$A,"S174-00.75", WMS용마재고!$L:$L) -> 0 | AR3: =SUMIF(WMS용마재고!$A:$A,"S174-01.00", WMS용마재고!$L:$L) -> 588 | AS3: =SUMIF(WMS용마재고!$A:$A,"S174-01.25", WMS용마재고!$L:$L) -> 762 | AT3: =SUMIF(WMS용마재고!$A:$A,"S174-01.50", WMS용마재고!$L:$L) -> 622 | AU3: =SUMIF(WMS용마재고!$A:$A,"S174-01.75", WMS용마재고!$L:$L) -> 599 | AV3: =SUMIF(WMS용마재고!$A:$A,"S174-02.00", WMS용마재고!$L:$L) -> 556 | AW3: =SUMIF(WMS용마재고!$A:$A,"S174-02.25", WMS용마재고!$L:$L) -> 606 | AX3: =SUMIF(WMS용마재고!$A:$A,"S174-02.50", WMS용마재고!$L:$L) -> 1141 | AY3: =SUMIF(WMS용마재고!$A:$A,"S174-02.75", WMS용마재고!$L:$L) -> 581 | AZ3: =SUMIF(WMS용마재고!$A:$A,"S174-03.00", WMS용마재고!$L:$L) -> 605 | BA3: =SUMIF(WMS용마재고!$A:$A,"S174-03.25", WMS용마재고!$L:$L) -> 724 | BB3: =SUMIF(WMS용마재고!$A:$A,"S174-03.50", WMS용마재고!$L:$L) -> 766 | BC3: =SUMIF(WMS용마재고!$A:$A,"S174-03.75", WMS용마재고!$L:$L) -> 686 | BD3: =SUMIF(WMS용마재고!$A:$A,"S174-04.00", WMS용마재고!$L:$L) -> 575 | BE3: =SUMIF(WMS용마재고!$A:$A,"S174-04.25", WMS용마재고!$L:$L) -> 584 | BF3: =SUMIF(WMS용마재고!$A:$A,"S174-04.50", WMS용마재고!$L:$L) -> 587 | BG3: =SUMIF(WMS용마재고!$A:$A,"S174-04.75", WMS용마재고!$L:$L) -> 585 | BH3: =SUMIF(WMS용마재고!$A:$A,"S174-05.00", WMS용마재고!$L:$L) -> 593 | BI3: =SUMIF(WMS용마재고!$A:$A,"S174-05.25", WMS용마재고!$L:$L) -> 0 | BJ3: =SUMIF(WMS용마재고!$A:$A,"S174-05.50", WMS용마재고!$L:$L) -> 613 | BK3: =SUMIF(WMS용마재고!$A:$A,"S174-05.75", WMS용마재고!$L:$L) -> 0 | BL3: =SUMIF(WMS용마재고!$A:$A,"S174-06.00", WMS용마재고!$L:$L) -> 616 | BM3: =SUMIF(WMS용마재고!$A:$A,"S174-06.50", WMS용마재고!$L:$L) -> 622 | BN3: =SUMIF(WMS용마재고!$A:$A,"S174-07.00", WMS용마재고!$L:$L) -> 537 | BO3: =SUMIF(WMS용마재고!$A:$A,"S174-07.50", WMS용마재고!$L:$L) -> 670 | BP3: =SUMIF(WMS용마재고!$A:$A,"S174-08.00", WMS용마재고!$L:$L) -> 659 | BQ3: =SUMIF(WMS용마재고!$A:$A,"S174-08.50", WMS용마재고!$L:$L) -> 0 | BR3: =SUMIF(WMS용마재고!$A:$A,"S174-09.00", WMS용마재고!$L:$L) -> 0 | BS3: =SUMIF(WMS용마재고!$A:$A,"S174-09.50", WMS용마재고!$L:$L) -> 0 | BT3: =SUMIF(WMS용마재고!$A:$A,"S174-10.00", WMS용마재고!$L:$L) -> 0 | BU3: =SUMIF(WMS용마재고!$A:$A,"s123-10.50", WMS용마재고!$L:$L) -> 0 | BV3: =SUMIF(WMS용마재고!$A:$A,"s123-10.50", WMS용마재고!$L:$L) -> 0 | BW3: =SUMIF(WMS용마재고!$A:$A,"s123-10.50", WMS용마재고!$L:$L) -> 0 | BX3: =SUMIF(WMS용마재고!$A:$A,"s123-10.50", WMS용마재고!$L:$L) -> 0 | BY3: 831 | BZ3: 0 | CA3: 0 | CB3: 588 | CC3: 762 | CD3: 622 | CE3: 599 | CF3: 556 | CG3: 606 | CH3: 1141 | CI3: 581 | CJ3: 605 | CK3: 724 | CL3: 766 | CM3: 686 | CN3: 575 | CO3: 584 | CP3: 587 | CQ3: 585 | CR3: 593 | CS3: 0 | CT3: 613 | CU3: 0 | CV3: 616 | CW3: 622 | CX3: 537 | CY3: 670 | CZ3: 659 | DA3: 0 | DB3: 0 | DC3: 0 | DD3: 0 | DE3: 0 | DF3: 0 | DG3: 0 | DH3: 0 | DI3: =IF(AND(BY3<30, AO3>=30), "증가", "") | DJ3: =IF(AND(BZ3<30, AP3>=30), "증가", "") | DK3: =IF(AND(CA3<30, AQ3>=30), "증가", "") | DL3: =IF(AND(CB3<30, AR3>=30), "증가", "") | DM3: =IF(AND(CC3<30, AS3>=30), "증가", "") | DN3: =IF(AND(CD3<30, AT3>=30), "증가", "") | DO3: =IF(AND(CE3<30, AU3>=30), "증가", "") | DP3: =IF(AND(CF3<30, AV3>=30), "증가", "") | ... ER3: =IF(AND(DH3<30, BX3>=30), "증가", "") | ES3: =IF(AND(AO3<30, BY3>=30), "경고", "") | ET3: =IF(AND(AP3<30, BZ3>=30), "경고", "") | EU3: =IF(AND(AQ3<30, CA3>=30), "경고", "") | EV3: =IF(AND(AR3<30, CB3>=30), "경고", "") | EW3: =IF(AND(AS3<30, CC3>=30), "경고", "") | EX3: =IF(AND(AT3<30, CD3>=30), "경고", "") | EY3: =IF(AND(AU3<30, CE3>=30), "경고", "") | EZ3: =IF(AND(AV3<30, CF3>=30), "경고", "") | ... GB3: =IF(AND(BX3<30, DH3>=30), "경고", "")
A4: 2 | B4: 미셀리아 Lake Gray | C4: =SUMIF(WMS용마재고!$A:$A,"S175-00.00", WMS용마재고!$L:$L) -> 553 | F4: =SUMIF(WMS용마재고!$A:$A,"S175-01.00", WMS용마재고!$L:$L) -> 554 | G4: =SUMIF(WMS용마재고!$A:$A,"S175-01.25", WMS용마재고!$L:$L) -> 572 | H4: =SUMIF(WMS용마재고!$A:$A,"S175-01.50", WMS용마재고!$L:$L) -> 555 | I4: =SUMIF(WMS용마재고!$A:$A,"S175-01.75", WMS용마재고!$L:$L) -> 559 | J4: =SUMIF(WMS용마재고!$A:$A,"S175-02.00", WMS용마재고!$L:$L) -> 568 | K4: =SUMIF(WMS용마재고!$A:$A,"S175-02.25", WMS용마재고!$L:$L) -> 564 | L4: =SUMIF(WMS용마재고!$A:$A,"S175-02.50", WMS용마재고!$L:$L) -> 580 | M4: =SUMIF(WMS용마재고!$A:$A,"S175-02.75", WMS용마재고!$L:$L) -> 631 | N4: =SUMIF(WMS용마재고!$A:$A,"S175-03.00", WMS용마재고!$L:$L) -> 605 | O4: =SUMIF(WMS용마재고!$A:$A,"S175-03.25", WMS용마재고!$L:$L) -> 543 | P4: =SUMIF(WMS용마재고!$A:$A,"S175-03.50", WMS용마재고!$L:$L) -> 571 | Q4: =SUMIF(WMS용마재고!$A:$A,"S175-03.75", WMS용마재고!$L:$L) -> 577 | R4: =SUMIF(WMS용마재고!$A:$A,"S175-04.00", WMS용마재고!$L:$L) -> 578 | S4: =SUMIF(WMS용마재고!$A:$A,"S175-04.25", WMS용마재고!$L:$L) -> 307 | T4: =SUMIF(WMS용마재고!$A:$A,"S175-04.50", WMS용마재고!$L:$L) -> 560 | U4: =SUMIF(WMS용마재고!$A:$A,"S175-04.75", WMS용마재고!$L:$L) -> 627 | V4: =SUMIF(WMS용마재고!$A:$A,"S175-05.00", WMS용마재고!$L:$L) -> 556 | X4: =SUMIF(WMS용마재고!$A:$A,"S175-05.50", WMS용마재고!$L:$L) -> 624 | Z4: =SUMIF(WMS용마재고!$A:$A,"S175-06.00", WMS용마재고!$L:$L) -> 600 | AA4: =SUMIF(WMS용마재고!$A:$A,"S175-06.50", WMS용마재고!$L:$L) -> 264 | AB4: =SUMIF(WMS용마재고!$A:$A,"S175-07.00", WMS용마재고!$L:$L) -> 625 | AC4: =SUMIF(WMS용마재고!$A:$A,"S175-07.50", WMS용마재고!$L:$L) -> 652 | AD4: =SUMIF(WMS용마재고!$A:$A,"S175-08.00", WMS용마재고!$L:$L) -> 597 | AN4: O2O2 D_Ash Brown EX | AO4: =SUMIF(WMS용마재고!$A:$A,"S175-00.00", WMS용마재고!$L:$L) -> 553 | AP4: =SUMIF(WMS용마재고!$A:$A,"S175-00.50", WMS용마재고!$L:$L) -> 0 | AQ4: =SUMIF(WMS용마재고!$A:$A,"S175-00.75", WMS용마재고!$L:$L) -> 0 | AR4: =SUMIF(WMS용마재고!$A:$A,"S175-01.00", WMS용마재고!$L:$L) -> 554 | AS4: =SUMIF(WMS용마재고!$A:$A,"S175-01.25", WMS용마재고!$L:$L) -> 572 | AT4: =SUMIF(WMS용마재고!$A:$A,"S175-01.50", WMS용마재고!$L:$L) -> 555 | AU4: =SUMIF(WMS용마재고!$A:$A,"S175-01.75", WMS용마재고!$L:$L) -> 559 | AV4: =SUMIF(WMS용마재고!$A:$A,"S175-02.00", WMS용마재고!$L:$L) -> 568 | AW4: =SUMIF(WMS용마재고!$A:$A,"S175-02.25", WMS용마재고!$L:$L) -> 564 | AX4: =SUMIF(WMS용마재고!$A:$A,"S175-02.50", WMS용마재고!$L:$L) -> 580 | AY4: =SUMIF(WMS용마재고!$A:$A,"S175-02.75", WMS용마재고!$L:$L) -> 631 | AZ4: =SUMIF(WMS용마재고!$A:$A,"S175-03.00", WMS용마재고!$L:$L) -> 605 | BA4: =SUMIF(WMS용마재고!$A:$A,"S175-03.25", WMS용마재고!$L:$L) -> 543 | BB4: =SUMIF(WMS용마재고!$A:$A,"S175-03.50", WMS용마재고!$L:$L) -> 571 | BC4: =SUMIF(WMS용마재고!$A:$A,"S175-03.75", WMS용마재고!$L:$L) -> 577 | BD4: =SUMIF(WMS용마재고!$A:$A,"S175-04.00", WMS용마재고!$L:$L) -> 578 | BE4: =SUMIF(WMS용마재고!$A:$A,"S175-04.25", WMS용마재고!$L:$L) -> 307 | BF4: =SUMIF(WMS용마재고!$A:$A,"S175-04.50", WMS용마재고!$L:$L) -> 560 | BG4: =SUMIF(WMS용마재고!$A:$A,"S175-04.75", WMS용마재고!$L:$L) -> 627 | BH4: =SUMIF(WMS용마재고!$A:$A,"S175-05.00", WMS용마재고!$L:$L) -> 556 | BI4: =SUMIF(WMS용마재고!$A:$A,"S175-05.25", WMS용마재고!$L:$L) -> 0 | BJ4: =SUMIF(WMS용마재고!$A:$A,"S175-05.50", WMS용마재고!$L:$L) -> 624 | BK4: =SUMIF(WMS용마재고!$A:$A,"S175-05.75", WMS용마재고!$L:$L) -> 0 | BL4: =SUMIF(WMS용마재고!$A:$A,"S175-06.00", WMS용마재고!$L:$L) -> 600 | BM4: =SUMIF(WMS용마재고!$A:$A,"S175-06.50", WMS용마재고!$L:$L) -> 264 | BN4: =SUMIF(WMS용마재고!$A:$A,"S175-07.00", WMS용마재고!$L:$L) -> 625 | BO4: =SUMIF(WMS용마재고!$A:$A,"S175-07.50", WMS용마재고!$L:$L) -> 652 | BP4: =SUMIF(WMS용마재고!$A:$A,"S175-08.00", WMS용마재고!$L:$L) -> 597 | BQ4: =SUMIF(WMS용마재고!$A:$A,"S175-08.50", WMS용마재고!$L:$L) -> 0 | BR4: =SUMIF(WMS용마재고!$A:$A,"S175-09.00", WMS용마재고!$L:$L) -> 0 | BS4: =SUMIF(WMS용마재고!$A:$A,"S175-09.50", WMS용마재고!$L:$L) -> 0 | BT4: =SUMIF(WMS용마재고!$A:$A,"S175-10.00", WMS용마재고!$L:$L) -> 0 | BV4: =SUMIF(WMS용마재고!$A:$A,"S175-10.50", WMS용마재고!$L:$L) -> 0 | BW4: =SUMIF(WMS용마재고!$A:$A,"S175-10.50", WMS용마재고!$L:$L) -> 0 | BX4: =SUMIF(WMS용마재고!$A:$A,"S175-10.50", WMS용마재고!$L:$L) -> 0 | BY4: 553 | BZ4: 0 | CA4: 0 | CB4: 554 | CC4: 572 | CD4: 555 | CE4: 559 | CF4: 568 | CG4: 564 | CH4: 580 | CI4: 631 | CJ4: 605 | CK4: 543 | CL4: 571 | CM4: 577 | CN4: 578 | CO4: 307 | CP4: 560 | CQ4: 627 | CR4: 556 | CS4: 0 | CT4: 624 | CU4: 0 | CV4: 600 | CW4: 264 | CX4: 625 | CY4: 652 | CZ4: 597 | DA4: 0 | DB4: 0 | DC4: 0 | DD4: 0 | DF4: 0 | DG4: 0 | DH4: 0 | DI4: =IF(AND(BY4<30, AO4>=30), "증가", "") | DJ4: =IF(AND(BZ4<30, AP4>=30), "증가", "") | DK4: =IF(AND(CA4<30, AQ4>=30), "증가", "") | DL4: =IF(AND(CB4<30, AR4>=30), "증가", "") | DM4: =IF(AND(CC4<30, AS4>=30), "증가", "") | DN4: =IF(AND(CD4<30, AT4>=30), "증가", "") | DO4: =IF(AND(CE4<30, AU4>=30), "증가", "") | DP4: =IF(AND(CF4<30, AV4>=30), "증가", "") | ... ER4: =IF(AND(DH4<30, BX4>=30), "증가", "") | ES4: =IF(AND(AO4<30, BY4>=30), "경고", "") | ET4: =IF(AND(AP4<30, BZ4>=30), "경고", "") | EU4: =IF(AND(AQ4<30, CA4>=30), "경고", "") | EV4: =IF(AND(AR4<30, CB4>=30), "경고", "") | EW4: =IF(AND(AS4<30, CC4>=30), "경고", "") | EX4: =IF(AND(AT4<30, CD4>=30), "경고", "") | EY4: =IF(AND(AU4<30, CE4>=30), "경고", "") | EZ4: =IF(AND(AV4<30, CF4>=30), "경고", "") | ... GB4: =IF(AND(BX4<30, DH4>=30), "경고", "")
A5: 3 | B5: 미셀리아 Mute Brown | C5: =SUMIF(WMS용마재고!$A:$A,"S176-00.00", WMS용마재고!$L:$L) -> 512 | F5: =SUMIF(WMS용마재고!$A:$A,"S176-01.00", WMS용마재고!$L:$L) -> 541 | G5: =SUMIF(WMS용마재고!$A:$A,"S176-01.25", WMS용마재고!$L:$L) -> 654 | H5: =SUMIF(WMS용마재고!$A:$A,"S176-01.50", WMS용마재고!$L:$L) -> 569 | I5: =SUMIF(WMS용마재고!$A:$A,"S176-01.75", WMS용마재고!$L:$L) -> 613 | J5: =SUMIF(WMS용마재고!$A:$A,"S176-02.00", WMS용마재고!$L:$L) -> 675 | K5: =SUMIF(WMS용마재고!$A:$A,"S176-02.25", WMS용마재고!$L:$L) -> 564 | L5: =SUMIF(WMS용마재고!$A:$A,"S176-02.50", WMS용마재고!$L:$L) -> 629 | M5: =SUMIF(WMS용마재고!$A:$A,"S176-02.75", WMS용마재고!$L:$L) -> 139 | N5: =SUMIF(WMS용마재고!$A:$A,"S176-03.00", WMS용마재고!$L:$L) -> 601 | O5: =SUMIF(WMS용마재고!$A:$A,"S176-03.25", WMS용마재고!$L:$L) -> 673 | P5: =SUMIF(WMS용마재고!$A:$A,"S176-03.50", WMS용마재고!$L:$L) -> 613 | Q5: =SUMIF(WMS용마재고!$A:$A,"S176-03.75", WMS용마재고!$L:$L) -> 640 | R5: =SUMIF(WMS용마재고!$A:$A,"S176-04.00", WMS용마재고!$L:$L) -> 623 | S5: =SUMIF(WMS용마재고!$A:$A,"S176-04.25", WMS용마재고!$L:$L) -> 582 | T5: =SUMIF(WMS용마재고!$A:$A,"S176-04.50", WMS용마재고!$L:$L) -> 594 | U5: =SUMIF(WMS용마재고!$A:$A,"S176-04.75", WMS용마재고!$L:$L) -> 620 | V5: =SUMIF(WMS용마재고!$A:$A,"S176-05.00", WMS용마재고!$L:$L) -> 605 | X5: =SUMIF(WMS용마재고!$A:$A,"S176-05.50", WMS용마재고!$L:$L) -> 355 | Z5: =SUMIF(WMS용마재고!$A:$A,"S176-06.00", WMS용마재고!$L:$L) -> 438 | AA5: =SUMIF(WMS용마재고!$A:$A,"S176-06.50", WMS용마재고!$L:$L) -> 636 | AB5: =SUMIF(WMS용마재고!$A:$A,"S176-07.00", WMS용마재고!$L:$L) -> 599 | AC5: =SUMIF(WMS용마재고!$A:$A,"S176-07.50", WMS용마재고!$L:$L) -> 629 | AD5: =SUMIF(WMS용마재고!$A:$A,"S176-08.00", WMS용마재고!$L:$L) -> 514 | AN5: O2O2 D_Ash Gray EX | AO5: =SUMIF(WMS용마재고!$A:$A,"S176-00.00", WMS용마재고!$L:$L) -> 512 | AP5: =SUMIF(WMS용마재고!$A:$A,"S176-00.50", WMS용마재고!$L:$L) -> 0 | AQ5: =SUMIF(WMS용마재고!$A:$A,"S176-00.75", WMS용마재고!$L:$L) -> 0 | AR5: =SUMIF(WMS용마재고!$A:$A,"S176-01.00", WMS용마재고!$L:$L) -> 541 | AS5: =SUMIF(WMS용마재고!$A:$A,"S176-01.25", WMS용마재고!$L:$L) -> 654 | AT5: =SUMIF(WMS용마재고!$A:$A,"S176-01.50", WMS용마재고!$L:$L) -> 569 | AU5: =SUMIF(WMS용마재고!$A:$A,"S176-01.75", WMS용마재고!$L:$L) -> 613 | AV5: =SUMIF(WMS용마재고!$A:$A,"S176-02.00", WMS용마재고!$L:$L) -> 675 | AW5: =SUMIF(WMS용마재고!$A:$A,"S176-02.25", WMS용마재고!$L:$L) -> 564 | AX5: =SUMIF(WMS용마재고!$A:$A,"S176-02.50", WMS용마재고!$L:$L) -> 629 | AY5: =SUMIF(WMS용마재고!$A:$A,"S176-02.75", WMS용마재고!$L:$L) -> 139 | AZ5: =SUMIF(WMS용마재고!$A:$A,"S176-03.00", WMS용마재고!$L:$L) -> 601 | BA5: =SUMIF(WMS용마재고!$A:$A,"S176-03.25", WMS용마재고!$L:$L) -> 673 | BB5: =SUMIF(WMS용마재고!$A:$A,"S176-03.50", WMS용마재고!$L:$L) -> 613 | BC5: =SUMIF(WMS용마재고!$A:$A,"S176-03.75", WMS용마재고!$L:$L) -> 640 | BD5: =SUMIF(WMS용마재고!$A:$A,"S176-04.00", WMS용마재고!$L:$L) -> 623 | BE5: =SUMIF(WMS용마재고!$A:$A,"S176-04.25", WMS용마재고!$L:$L) -> 582 | BF5: =SUMIF(WMS용마재고!$A:$A,"S176-04.50", WMS용마재고!$L:$L) -> 594 | BG5: =SUMIF(WMS용마재고!$A:$A,"S176-04.75", WMS용마재고!$L:$L) -> 620 | BH5: =SUMIF(WMS용마재고!$A:$A,"S176-05.00", WMS용마재고!$L:$L) -> 605 | BI5: =SUMIF(WMS용마재고!$A:$A,"S176-05.25", WMS용마재고!$L:$L) -> 0 | BJ5: =SUMIF(WMS용마재고!$A:$A,"S176-05.50", WMS용마재고!$L:$L) -> 355 | BK5: =SUMIF(WMS용마재고!$A:$A,"S176-05.75", WMS용마재고!$L:$L) -> 0 | BL5: =SUMIF(WMS용마재고!$A:$A,"S176-06.00", WMS용마재고!$L:$L) -> 438 | BM5: =SUMIF(WMS용마재고!$A:$A,"S176-06.50", WMS용마재고!$L:$L) -> 636 | BN5: =SUMIF(WMS용마재고!$A:$A,"S176-07.00", WMS용마재고!$L:$L) -> 599 | BO5: =SUMIF(WMS용마재고!$A:$A,"S176-07.50", WMS용마재고!$L:$L) -> 629 | BP5: =SUMIF(WMS용마재고!$A:$A,"S176-08.00", WMS용마재고!$L:$L) -> 514 | BQ5: =SUMIF(WMS용마재고!$A:$A,"S176-08.50", WMS용마재고!$L:$L) -> 0 | BR5: =SUMIF(WMS용마재고!$A:$A,"S176-09.00", WMS용마재고!$L:$L) -> 0 | BS5: =SUMIF(WMS용마재고!$A:$A,"S176-09.50", WMS용마재고!$L:$L) -> 0 | BT5: =SUMIF(WMS용마재고!$A:$A,"S176-10.00", WMS용마재고!$L:$L) -> 0 | BU5: =SUMIF(WMS용마재고!$A:$A,"S617-10.50", WMS용마재고!$L:$L) -> 0 | BV5: =SUMIF(WMS용마재고!$A:$A,"S617-10.50", WMS용마재고!$L:$L) -> 0 | BW5: =SUMIF(WMS용마재고!$A:$A,"S617-10.50", WMS용마재고!$L:$L) -> 0 | BX5: =SUMIF(WMS용마재고!$A:$A,"S617-10.50", WMS용마재고!$L:$L) -> 0 | BY5: 512 | BZ5: 0 | CA5: 0 | CB5: 541 | CC5: 654 | CD5: 569 | CE5: 613 | CF5: 675 | CG5: 564 | CH5: 629 | CI5: 139 | CJ5: 601 | CK5: 673 | CL5: 613 | CM5: 640 | CN5: 623 | CO5: 582 | CP5: 594 | CQ5: 620 | CR5: 605 | CS5: 0 | CT5: 355 | CU5: 0 | CV5: 438 | CW5: 636 | CX5: 599 | CY5: 629 | CZ5: 514 | DA5: 0 | DB5: 0 | DC5: 0 | DD5: 0 | DE5: 0 | DF5: 0 | DG5: 0 | DH5: 0 | DI5: =IF(AND(BY5<30, AO5>=30), "증가", "") | DJ5: =IF(AND(BZ5<30, AP5>=30), "증가", "") | DK5: =IF(AND(CA5<30, AQ5>=30), "증가", "") | DL5: =IF(AND(CB5<30, AR5>=30), "증가", "") | DM5: =IF(AND(CC5<30, AS5>=30), "증가", "") | DN5: =IF(AND(CD5<30, AT5>=30), "증가", "") | DO5: =IF(AND(CE5<30, AU5>=30), "증가", "") | DP5: =IF(AND(CF5<30, AV5>=30), "증가", "") | ... ER5: =IF(AND(DH5<30, BX5>=30), "증가", "") | ES5: =IF(AND(AO5<30, BY5>=30), "경고", "") | ET5: =IF(AND(AP5<30, BZ5>=30), "경고", "") | EU5: =IF(AND(AQ5<30, CA5>=30), "경고", "") | EV5: =IF(AND(AR5<30, CB5>=30), "경고", "") | EW5: =IF(AND(AS5<30, CC5>=30), "경고", "") | EX5: =IF(AND(AT5<30, CD5>=30), "경고", "") | EY5: =IF(AND(AU5<30, CE5>=30), "경고", "") | EZ5: =IF(AND(AV5<30, CF5>=30), "경고", "") | ... GB5: =IF(AND(BX5<30, DH5>=30), "경고", "")
A6: 4 | B6: 미셀리아 Pale Choco | C6: =SUMIF(WMS용마재고!$A:$A,"S317-00.00", WMS용마재고!$L:$L) -> 317 | F6: =SUMIF(WMS용마재고!$A:$A,"S317-01.00", WMS용마재고!$L:$L) -> 301 | G6: =SUMIF(WMS용마재고!$A:$A,"S317-01.25", WMS용마재고!$L:$L) -> 291 | H6: =SUMIF(WMS용마재고!$A:$A,"S317-01.50", WMS용마재고!$L:$L) -> 299 | I6: =SUMIF(WMS용마재고!$A:$A,"S317-01.75", WMS용마재고!$L:$L) -> 288 | J6: =SUMIF(WMS용마재고!$A:$A,"S317-02.00", WMS용마재고!$L:$L) -> 267 | K6: =SUMIF(WMS용마재고!$A:$A,"S317-02.25", WMS용마재고!$L:$L) -> 271 | L6: =SUMIF(WMS용마재고!$A:$A,"S317-02.50", WMS용마재고!$L:$L) -> 305 | M6: =SUMIF(WMS용마재고!$A:$A,"S317-02.75", WMS용마재고!$L:$L) -> 303 | N6: =SUMIF(WMS용마재고!$A:$A,"S317-03.00", WMS용마재고!$L:$L) -> 294 | O6: =SUMIF(WMS용마재고!$A:$A,"S317-03.25", WMS용마재고!$L:$L) -> 270 | P6: =SUMIF(WMS용마재고!$A:$A,"S317-03.50", WMS용마재고!$L:$L) -> 276 | Q6: =SUMIF(WMS용마재고!$A:$A,"S317-03.75", WMS용마재고!$L:$L) -> 277 | R6: =SUMIF(WMS용마재고!$A:$A,"S317-04.00", WMS용마재고!$L:$L) -> 267 | S6: =SUMIF(WMS용마재고!$A:$A,"S317-04.25", WMS용마재고!$L:$L) -> 253 | T6: =SUMIF(WMS용마재고!$A:$A,"S317-04.50", WMS용마재고!$L:$L) -> 257 | U6: =SUMIF(WMS용마재고!$A:$A,"S317-04.75", WMS용마재고!$L:$L) -> 263 | V6: =SUMIF(WMS용마재고!$A:$A,"S317-05.00", WMS용마재고!$L:$L) -> 263 | X6: =SUMIF(WMS용마재고!$A:$A,"S317-05.50", WMS용마재고!$L:$L) -> 278 | Z6: =SUMIF(WMS용마재고!$A:$A,"S317-06.00", WMS용마재고!$L:$L) -> 292 | AA6: =SUMIF(WMS용마재고!$A:$A,"S317-06.50", WMS용마재고!$L:$L) -> 216 | AB6: =SUMIF(WMS용마재고!$A:$A,"S317-07.00", WMS용마재고!$L:$L) -> 342 | AC6: =SUMIF(WMS용마재고!$A:$A,"S317-07.50", WMS용마재고!$L:$L) -> 358 | AD6: =SUMIF(WMS용마재고!$A:$A,"S317-08.00", WMS용마재고!$L:$L) -> 364 | AN6: O2O2 D_Ash Gray EX | AO6: =SUMIF(WMS용마재고!$A:$A,"S317-00.00", WMS용마재고!$L:$L) -> 317 | AP6: =SUMIF(WMS용마재고!$A:$A,"S317-00.50", WMS용마재고!$L:$L) -> 0 | AQ6: =SUMIF(WMS용마재고!$A:$A,"S317-00.75", WMS용마재고!$L:$L) -> 0 | AR6: =SUMIF(WMS용마재고!$A:$A,"S317-01.00", WMS용마재고!$L:$L) -> 301 | AS6: =SUMIF(WMS용마재고!$A:$A,"S317-01.25", WMS용마재고!$L:$L) -> 291 | AT6: =SUMIF(WMS용마재고!$A:$A,"S317-01.50", WMS용마재고!$L:$L) -> 299 | AU6: =SUMIF(WMS용마재고!$A:$A,"S317-01.75", WMS용마재고!$L:$L) -> 288 | AV6: =SUMIF(WMS용마재고!$A:$A,"S317-02.00", WMS용마재고!$L:$L) -> 267 | AW6: =SUMIF(WMS용마재고!$A:$A,"S317-02.25", WMS용마재고!$L:$L) -> 271 | AX6: =SUMIF(WMS용마재고!$A:$A,"S317-02.50", WMS용마재고!$L:$L) -> 305 | AY6: =SUMIF(WMS용마재고!$A:$A,"S317-02.75", WMS용마재고!$L:$L) -> 303 | AZ6: =SUMIF(WMS용마재고!$A:$A,"S317-03.00", WMS용마재고!$L:$L) -> 294 | BA6: =SUMIF(WMS용마재고!$A:$A,"S317-03.25", WMS용마재고!$L:$L) -> 270 | BB6: =SUMIF(WMS용마재고!$A:$A,"S317-03.50", WMS용마재고!$L:$L) -> 276 | BC6: =SUMIF(WMS용마재고!$A:$A,"S317-03.75", WMS용마재고!$L:$L) -> 277 | BD6: =SUMIF(WMS용마재고!$A:$A,"S317-04.00", WMS용마재고!$L:$L) -> 267 | BE6: =SUMIF(WMS용마재고!$A:$A,"S317-04.25", WMS용마재고!$L:$L) -> 253 | BF6: =SUMIF(WMS용마재고!$A:$A,"S317-04.50", WMS용마재고!$L:$L) -> 257 | BG6: =SUMIF(WMS용마재고!$A:$A,"S317-04.75", WMS용마재고!$L:$L) -> 263 | BH6: =SUMIF(WMS용마재고!$A:$A,"S317-05.00", WMS용마재고!$L:$L) -> 263 | BI6: =SUMIF(WMS용마재고!$A:$A,"S317-05.25", WMS용마재고!$L:$L) -> 0 | BJ6: =SUMIF(WMS용마재고!$A:$A,"S317-05.50", WMS용마재고!$L:$L) -> 278 | BK6: =SUMIF(WMS용마재고!$A:$A,"S317-05.75", WMS용마재고!$L:$L) -> 0 | BL6: =SUMIF(WMS용마재고!$A:$A,"S317-06.00", WMS용마재고!$L:$L) -> 292 | BM6: =SUMIF(WMS용마재고!$A:$A,"S317-06.50", WMS용마재고!$L:$L) -> 216 | BN6: =SUMIF(WMS용마재고!$A:$A,"S317-07.00", WMS용마재고!$L:$L) -> 342 | BO6: =SUMIF(WMS용마재고!$A:$A,"S317-07.50", WMS용마재고!$L:$L) -> 358 | BP6: =SUMIF(WMS용마재고!$A:$A,"S317-08.00", WMS용마재고!$L:$L) -> 364 | BQ6: =SUMIF(WMS용마재고!$A:$A,"S317-08.50", WMS용마재고!$L:$L) -> 0 | BR6: =SUMIF(WMS용마재고!$A:$A,"S317-09.00", WMS용마재고!$L:$L) -> 0 | BS6: =SUMIF(WMS용마재고!$A:$A,"S317-09.50", WMS용마재고!$L:$L) -> 0 | BT6: =SUMIF(WMS용마재고!$A:$A,"S317-10.00", WMS용마재고!$L:$L) -> 0 | BU6: =SUMIF(WMS용마재고!$A:$A,"S617-10.50", WMS용마재고!$L:$L) -> 0 | BV6: =SUMIF(WMS용마재고!$A:$A,"S617-10.50", WMS용마재고!$L:$L) -> 0 | BW6: =SUMIF(WMS용마재고!$A:$A,"S617-10.50", WMS용마재고!$L:$L) -> 0 | BX6: =SUMIF(WMS용마재고!$A:$A,"S617-10.50", WMS용마재고!$L:$L) -> 0 | BY6: 317 | BZ6: 0 | CA6: 0 | CB6: 301 | CC6: 291 | CD6: 299 | CE6: 288 | CF6: 267 | CG6: 271 | CH6: 305 | CI6: 303 | CJ6: 294 | CK6: 270 | CL6: 276 | CM6: 277 | CN6: 267 | CO6: 253 | CP6: 257 | CQ6: 263 | CR6: 263 | CS6: 0 | CT6: 278 | CU6: 0 | CV6: 292 | CW6: 216 | CX6: 342 | CY6: 358 | CZ6: 364 | DA6: 0 | DB6: 0 | DC6: 0 | DD6: 0 | DE6: 0 | DF6: 0 | DG6: 0 | DH6: 0 | DI6: =IF(AND(BY6<30, AO6>=30), "증가", "") | DJ6: =IF(AND(BZ6<30, AP6>=30), "증가", "") | DK6: =IF(AND(CA6<30, AQ6>=30), "증가", "") | DL6: =IF(AND(CB6<30, AR6>=30), "증가", "") | DM6: =IF(AND(CC6<30, AS6>=30), "증가", "") | DN6: =IF(AND(CD6<30, AT6>=30), "증가", "") | DO6: =IF(AND(CE6<30, AU6>=30), "증가", "") | DP6: =IF(AND(CF6<30, AV6>=30), "증가", "") | ... ER6: =IF(AND(DH6<30, BX6>=30), "증가", "") | ES6: =IF(AND(AO6<30, BY6>=30), "경고", "") | ET6: =IF(AND(AP6<30, BZ6>=30), "경고", "") | EU6: =IF(AND(AQ6<30, CA6>=30), "경고", "") | EV6: =IF(AND(AR6<30, CB6>=30), "경고", "") | EW6: =IF(AND(AS6<30, CC6>=30), "경고", "") | EX6: =IF(AND(AT6<30, CD6>=30), "경고", "") | EY6: =IF(AND(AU6<30, CE6>=30), "경고", "") | EZ6: =IF(AND(AV6<30, CF6>=30), "경고", "") | ... GB6: =IF(AND(BX6<30, DH6>=30), "경고", "")
A7: * 미셀리아 10P
A8: 5 | B8: 미셀리아 Deep Black 10P | C8: =SUMIF(WMS용마재고!$A:$A,"S300-00.00", WMS용마재고!$L:$L) -> 646 | F8: =SUMIF(WMS용마재고!$A:$A,"S300-01.00", WMS용마재고!$L:$L) -> 420 | G8: =SUMIF(WMS용마재고!$A:$A,"S300-01.25", WMS용마재고!$L:$L) -> 340 | H8: =SUMIF(WMS용마재고!$A:$A,"S300-01.50", WMS용마재고!$L:$L) -> 498 | I8: =SUMIF(WMS용마재고!$A:$A,"S300-01.75", WMS용마재고!$L:$L) -> 470 | J8: =SUMIF(WMS용마재고!$A:$A,"S300-02.00", WMS용마재고!$L:$L) -> 340 | K8: =SUMIF(WMS용마재고!$A:$A,"S300-02.25", WMS용마재고!$L:$L) -> 491 | L8: =SUMIF(WMS용마재고!$A:$A,"S300-02.50", WMS용마재고!$L:$L) -> 379 | M8: =SUMIF(WMS용마재고!$A:$A,"S300-02.75", WMS용마재고!$L:$L) -> 360 | N8: =SUMIF(WMS용마재고!$A:$A,"S300-03.00", WMS용마재고!$L:$L) -> 357 | O8: =SUMIF(WMS용마재고!$A:$A,"S300-03.25", WMS용마재고!$L:$L) -> 340 | P8: =SUMIF(WMS용마재고!$A:$A,"S300-03.50", WMS용마재고!$L:$L) -> 340 | Q8: =SUMIF(WMS용마재고!$A:$A,"S300-03.75", WMS용마재고!$L:$L) -> 340 | R8: =SUMIF(WMS용마재고!$A:$A,"S300-04.00", WMS용마재고!$L:$L) -> 340 | S8: =SUMIF(WMS용마재고!$A:$A,"S300-04.25", WMS용마재고!$L:$L) -> 340 | T8: =SUMIF(WMS용마재고!$A:$A,"S300-04.50", WMS용마재고!$L:$L) -> 340 | U8: =SUMIF(WMS용마재고!$A:$A,"S300-04.75", WMS용마재고!$L:$L) -> 360 | V8: =SUMIF(WMS용마재고!$A:$A,"S300-05.00", WMS용마재고!$L:$L) -> 340 | X8: =SUMIF(WMS용마재고!$A:$A,"S300-05.50", WMS용마재고!$L:$L) -> 380 | Z8: =SUMIF(WMS용마재고!$A:$A,"S300-06.00", WMS용마재고!$L:$L) -> 340 | AA8: =SUMIF(WMS용마재고!$A:$A,"S300-06.50", WMS용마재고!$L:$L) -> 320 | AB8: =SUMIF(WMS용마재고!$A:$A,"S300-07.00", WMS용마재고!$L:$L) -> 155 | AC8: =SUMIF(WMS용마재고!$A:$A,"S300-07.50", WMS용마재고!$L:$L) -> 320 | AD8: =SUMIF(WMS용마재고!$A:$A,"S300-08.00", WMS용마재고!$L:$L) -> 281 | AN8: O2O2 D_Sepia Choco | AO8: =SUMIF(WMS용마재고!$A:$A,"S300-00.00", WMS용마재고!$L:$L) -> 646 | AP8: =SUMIF(WMS용마재고!$A:$A,"S300-00.50", WMS용마재고!$L:$L) -> 0 | AQ8: =SUMIF(WMS용마재고!$A:$A,"S300-00.75", WMS용마재고!$L:$L) -> 0 | AR8: =SUMIF(WMS용마재고!$A:$A,"S300-01.00", WMS용마재고!$L:$L) -> 420 | AS8: =SUMIF(WMS용마재고!$A:$A,"S300-01.25", WMS용마재고!$L:$L) -> 340 | AT8: =SUMIF(WMS용마재고!$A:$A,"S300-01.50", WMS용마재고!$L:$L) -> 498 | AU8: =SUMIF(WMS용마재고!$A:$A,"S300-01.75", WMS용마재고!$L:$L) -> 470 | AV8: =SUMIF(WMS용마재고!$A:$A,"S300-02.00", WMS용마재고!$L:$L) -> 340 | AW8: =SUMIF(WMS용마재고!$A:$A,"S300-02.25", WMS용마재고!$L:$L) -> 491 | AX8: =SUMIF(WMS용마재고!$A:$A,"S300-02.50", WMS용마재고!$L:$L) -> 379 | AY8: =SUMIF(WMS용마재고!$A:$A,"S300-02.75", WMS용마재고!$L:$L) -> 360 | AZ8: =SUMIF(WMS용마재고!$A:$A,"S300-03.00", WMS용마재고!$L:$L) -> 357 | BA8: =SUMIF(WMS용마재고!$A:$A,"S300-03.25", WMS용마재고!$L:$L) -> 340 | BB8: =SUMIF(WMS용마재고!$A:$A,"S300-03.50", WMS용마재고!$L:$L) -> 340 | BC8: =SUMIF(WMS용마재고!$A:$A,"S300-03.75", WMS용마재고!$L:$L) -> 340 | BD8: =SUMIF(WMS용마재고!$A:$A,"S300-04.00", WMS용마재고!$L:$L) -> 340 | BE8: =SUMIF(WMS용마재고!$A:$A,"S300-04.25", WMS용마재고!$L:$L) -> 340 | BF8: =SUMIF(WMS용마재고!$A:$A,"S300-04.50", WMS용마재고!$L:$L) -> 340 | BG8: =SUMIF(WMS용마재고!$A:$A,"S300-04.75", WMS용마재고!$L:$L) -> 360 | BH8: =SUMIF(WMS용마재고!$A:$A,"S300-05.00", WMS용마재고!$L:$L) -> 340 | BI8: =SUMIF(WMS용마재고!$A:$A,"S300-05.25", WMS용마재고!$L:$L) -> 0 | BJ8: =SUMIF(WMS용마재고!$A:$A,"S300-05.50", WMS용마재고!$L:$L) -> 380 | BK8: =SUMIF(WMS용마재고!$A:$A,"S300-05.75", WMS용마재고!$L:$L) -> 0 | BL8: =SUMIF(WMS용마재고!$A:$A,"S300-06.00", WMS용마재고!$L:$L) -> 340 | BM8: =SUMIF(WMS용마재고!$A:$A,"S300-06.50", WMS용마재고!$L:$L) -> 320 | BN8: =SUMIF(WMS용마재고!$A:$A,"S300-07.00", WMS용마재고!$L:$L) -> 155 | BO8: =SUMIF(WMS용마재고!$A:$A,"S300-07.50", WMS용마재고!$L:$L) -> 320 | BP8: =SUMIF(WMS용마재고!$A:$A,"S300-08.00", WMS용마재고!$L:$L) -> 281 | BQ8: =SUMIF(WMS용마재고!$A:$A,"S300-08.50", WMS용마재고!$L:$L) -> 0 | BR8: =SUMIF(WMS용마재고!$A:$A,"S300-09.00", WMS용마재고!$L:$L) -> 0 | BS8: =SUMIF(WMS용마재고!$A:$A,"S300-09.50", WMS용마재고!$L:$L) -> 0 | BT8: =SUMIF(WMS용마재고!$A:$A,"S300-10.00", WMS용마재고!$L:$L) -> 0 | BU8: =SUMIF(WMS용마재고!$A:$A,"s123-10.50", WMS용마재고!$L:$L) -> 0 | BV8: =SUMIF(WMS용마재고!$A:$A,"s123-10.50", WMS용마재고!$L:$L) -> 0 | BW8: =SUMIF(WMS용마재고!$A:$A,"s123-10.50", WMS용마재고!$L:$L) -> 0 | BX8: =SUMIF(WMS용마재고!$A:$A,"s123-10.50", WMS용마재고!$L:$L) -> 0 | BY8: 646 | BZ8: 0 | CA8: 0 | CB8: 420 | CC8: 340 | CD8: 498 | CE8: 470 | CF8: 340 | CG8: 491 | CH8: 379 | CI8: 360 | CJ8: 357 | CK8: 340 | CL8: 340 | CM8: 340 | CN8: 340 | CO8: 340 | CP8: 340 | CQ8: 360 | CR8: 340 | CS8: 0 | CT8: 380 | CU8: 0 | CV8: 340 | CW8: 320 | CX8: 155 | CY8: 320 | CZ8: 281 | DA8: 0 | DB8: 0 | DC8: 0 | DD8: 0 | DE8: 0 | DF8: 0 | DG8: 0 | DH8: 0 | DI8: =IF(AND(BY8<30, AO8>=30), "증가", "") | DJ8: =IF(AND(BZ8<30, AP8>=30), "증가", "") | DK8: =IF(AND(CA8<30, AQ8>=30), "증가", "") | DL8: =IF(AND(CB8<30, AR8>=30), "증가", "") | DM8: =IF(AND(CC8<30, AS8>=30), "증가", "") | DN8: =IF(AND(CD8<30, AT8>=30), "증가", "") | DO8: =IF(AND(CE8<30, AU8>=30), "증가", "") | DP8: =IF(AND(CF8<30, AV8>=30), "증가", "") | ... ER8: =IF(AND(DH8<30, BX8>=30), "증가", "") | ES8: =IF(AND(AO8<30, BY8>=30), "경고", "") | ET8: =IF(AND(AP8<30, BZ8>=30), "경고", "") | EU8: =IF(AND(AQ8<30, CA8>=30), "경고", "") | EV8: =IF(AND(AR8<30, CB8>=30), "경고", "") | EW8: =IF(AND(AS8<30, CC8>=30), "경고", "") | EX8: =IF(AND(AT8<30, CD8>=30), "경고", "") | EY8: =IF(AND(AU8<30, CE8>=30), "경고", "") | EZ8: =IF(AND(AV8<30, CF8>=30), "경고", "") | ... GB8: =IF(AND(BX8<30, DH8>=30), "경고", "")
A9: 6 | B9: 미셀리아 Lake Gray 10P | C9: =SUMIF(WMS용마재고!$A:$A,"S308-00.00", WMS용마재고!$L:$L) -> 420 | F9: =SUMIF(WMS용마재고!$A:$A,"S308-01.00", WMS용마재고!$L:$L) -> 340 | G9: =SUMIF(WMS용마재고!$A:$A,"S308-01.25", WMS용마재고!$L:$L) -> 300 | H9: =SUMIF(WMS용마재고!$A:$A,"S308-01.50", WMS용마재고!$L:$L) -> 320 | I9: =SUMIF(WMS용마재고!$A:$A,"S308-01.75", WMS용마재고!$L:$L) -> 360 | J9: =SUMIF(WMS용마재고!$A:$A,"S308-02.00", WMS용마재고!$L:$L) -> 320 | K9: =SUMIF(WMS용마재고!$A:$A,"S308-02.25", WMS용마재고!$L:$L) -> 320 | L9: =SUMIF(WMS용마재고!$A:$A,"S308-02.50", WMS용마재고!$L:$L) -> 360 | M9: =SUMIF(WMS용마재고!$A:$A,"S308-02.75", WMS용마재고!$L:$L) -> 360 | N9: =SUMIF(WMS용마재고!$A:$A,"S308-03.00", WMS용마재고!$L:$L) -> 360 | O9: =SUMIF(WMS용마재고!$A:$A,"S308-03.25", WMS용마재고!$L:$L) -> 380 | P9: =SUMIF(WMS용마재고!$A:$A,"S308-03.50", WMS용마재고!$L:$L) -> 300 | Q9: =SUMIF(WMS용마재고!$A:$A,"S308-03.75", WMS용마재고!$L:$L) -> 340 | R9: =SUMIF(WMS용마재고!$A:$A,"S308-04.00", WMS용마재고!$L:$L) -> 360 | S9: =SUMIF(WMS용마재고!$A:$A,"S308-04.25", WMS용마재고!$L:$L) -> 300 | T9: =SUMIF(WMS용마재고!$A:$A,"S308-04.50", WMS용마재고!$L:$L) -> 360 | U9: =SUMIF(WMS용마재고!$A:$A,"S308-04.75", WMS용마재고!$L:$L) -> 320 | V9: =SUMIF(WMS용마재고!$A:$A,"S308-05.00", WMS용마재고!$L:$L) -> 300 | X9: =SUMIF(WMS용마재고!$A:$A,"S308-05.50", WMS용마재고!$L:$L) -> 380 | Z9: =SUMIF(WMS용마재고!$A:$A,"S308-06.00", WMS용마재고!$L:$L) -> 400 | AA9: =SUMIF(WMS용마재고!$A:$A,"S308-06.50", WMS용마재고!$L:$L) -> 300 | AB9: =SUMIF(WMS용마재고!$A:$A,"S308-07.00", WMS용마재고!$L:$L) -> 320 | AC9: =SUMIF(WMS용마재고!$A:$A,"S308-07.50", WMS용마재고!$L:$L) -> 300 | AD9: =SUMIF(WMS용마재고!$A:$A,"S308-08.00", WMS용마재고!$L:$L) -> 300 | AN9: O2O2 D_Ash Brown EX | AO9: =SUMIF(WMS용마재고!$A:$A,"S308-00.00", WMS용마재고!$L:$L) -> 420 | AP9: =SUMIF(WMS용마재고!$A:$A,"S308-00.50", WMS용마재고!$L:$L) -> 0 | AQ9: =SUMIF(WMS용마재고!$A:$A,"S308-00.75", WMS용마재고!$L:$L) -> 0 | AR9: =SUMIF(WMS용마재고!$A:$A,"S308-01.00", WMS용마재고!$L:$L) -> 340 | AS9: =SUMIF(WMS용마재고!$A:$A,"S308-01.25", WMS용마재고!$L:$L) -> 300 | AT9: =SUMIF(WMS용마재고!$A:$A,"S308-01.50", WMS용마재고!$L:$L) -> 320 | AU9: =SUMIF(WMS용마재고!$A:$A,"S308-01.75", WMS용마재고!$L:$L) -> 360 | AV9: =SUMIF(WMS용마재고!$A:$A,"S308-02.00", WMS용마재고!$L:$L) -> 320 | AW9: =SUMIF(WMS용마재고!$A:$A,"S308-02.25", WMS용마재고!$L:$L) -> 320 | AX9: =SUMIF(WMS용마재고!$A:$A,"S308-02.50", WMS용마재고!$L:$L) -> 360 | AY9: =SUMIF(WMS용마재고!$A:$A,"S308-02.75", WMS용마재고!$L:$L) -> 360 | AZ9: =SUMIF(WMS용마재고!$A:$A,"S308-03.00", WMS용마재고!$L:$L) -> 360 | BA9: =SUMIF(WMS용마재고!$A:$A,"S308-03.25", WMS용마재고!$L:$L) -> 380 | BB9: =SUMIF(WMS용마재고!$A:$A,"S308-03.50", WMS용마재고!$L:$L) -> 300 | BC9: =SUMIF(WMS용마재고!$A:$A,"S308-03.75", WMS용마재고!$L:$L) -> 340 | BD9: =SUMIF(WMS용마재고!$A:$A,"S308-04.00", WMS용마재고!$L:$L) -> 360 | BE9: =SUMIF(WMS용마재고!$A:$A,"S308-04.25", WMS용마재고!$L:$L) -> 300 | BF9: =SUMIF(WMS용마재고!$A:$A,"S308-04.50", WMS용마재고!$L:$L) -> 360 | BG9: =SUMIF(WMS용마재고!$A:$A,"S308-04.75", WMS용마재고!$L:$L) -> 320 | BH9: =SUMIF(WMS용마재고!$A:$A,"S308-05.00", WMS용마재고!$L:$L) -> 300 | BI9: =SUMIF(WMS용마재고!$A:$A,"S308-05.25", WMS용마재고!$L:$L) -> 0 | BJ9: =SUMIF(WMS용마재고!$A:$A,"S308-05.50", WMS용마재고!$L:$L) -> 380 | BK9: =SUMIF(WMS용마재고!$A:$A,"S308-05.75", WMS용마재고!$L:$L) -> 0 | BL9: =SUMIF(WMS용마재고!$A:$A,"S308-06.00", WMS용마재고!$L:$L) -> 400 | BM9: =SUMIF(WMS용마재고!$A:$A,"S308-06.50", WMS용마재고!$L:$L) -> 300 | BN9: =SUMIF(WMS용마재고!$A:$A,"S308-07.00", WMS용마재고!$L:$L) -> 320 | BO9: =SUMIF(WMS용마재고!$A:$A,"S308-07.50", WMS용마재고!$L:$L) -> 300 | BP9: =SUMIF(WMS용마재고!$A:$A,"S308-08.00", WMS용마재고!$L:$L) -> 300 | BQ9: =SUMIF(WMS용마재고!$A:$A,"S308-08.50", WMS용마재고!$L:$L) -> 0 | BR9: =SUMIF(WMS용마재고!$A:$A,"S308-09.00", WMS용마재고!$L:$L) -> 0 | BS9: =SUMIF(WMS용마재고!$A:$A,"S308-09.50", WMS용마재고!$L:$L) -> 0 | BT9: =SUMIF(WMS용마재고!$A:$A,"S308-10.00", WMS용마재고!$L:$L) -> 0 | BV9: =SUMIF(WMS용마재고!$A:$A,"S308-10.50", WMS용마재고!$L:$L) -> 0 | BW9: =SUMIF(WMS용마재고!$A:$A,"S308-10.50", WMS용마재고!$L:$L) -> 0 | BX9: =SUMIF(WMS용마재고!$A:$A,"S308-10.50", WMS용마재고!$L:$L) -> 0 | BY9: 420 | BZ9: 0 | CA9: 0 | CB9: 340 | CC9: 300 | CD9: 320 | CE9: 360 | CF9: 320 | CG9: 320 | CH9: 360 | CI9: 360 | CJ9: 360 | CK9: 380 | CL9: 300 | CM9: 340 | CN9: 360 | CO9: 300 | CP9: 360 | CQ9: 320 | CR9: 300 | CS9: 0 | CT9: 380 | CU9: 0 | CV9: 400 | CW9: 300 | CX9: 320 | CY9: 300 | CZ9: 300 | DA9: 0 | DB9: 0 | DC9: 0 | DD9: 0 | DF9: 0 | DG9: 0 | DH9: 0 | DI9: =IF(AND(BY9<30, AO9>=30), "증가", "") | DJ9: =IF(AND(BZ9<30, AP9>=30), "증가", "") | DK9: =IF(AND(CA9<30, AQ9>=30), "증가", "") | DL9: =IF(AND(CB9<30, AR9>=30), "증가", "") | DM9: =IF(AND(CC9<30, AS9>=30), "증가", "") | DN9: =IF(AND(CD9<30, AT9>=30), "증가", "") | DO9: =IF(AND(CE9<30, AU9>=30), "증가", "") | DP9: =IF(AND(CF9<30, AV9>=30), "증가", "") | ... ER9: =IF(AND(DH9<30, BX9>=30), "증가", "") | ES9: =IF(AND(AO9<30, BY9>=30), "경고", "") | ET9: =IF(AND(AP9<30, BZ9>=30), "경고", "") | EU9: =IF(AND(AQ9<30, CA9>=30), "경고", "") | EV9: =IF(AND(AR9<30, CB9>=30), "경고", "") | EW9: =IF(AND(AS9<30, CC9>=30), "경고", "") | EX9: =IF(AND(AT9<30, CD9>=30), "경고", "") | EY9: =IF(AND(AU9<30, CE9>=30), "경고", "") | EZ9: =IF(AND(AV9<30, CF9>=30), "경고", "") | ... GB9: =IF(AND(BX9<30, DH9>=30), "경고", "")
A10: 7 | B10: 미셀리아 Mute Brown 10P | C10: =SUMIF(WMS용마재고!$A:$A,"S309-00.00", WMS용마재고!$L:$L) -> 478 | F10: =SUMIF(WMS용마재고!$A:$A,"S309-01.00", WMS용마재고!$L:$L) -> 537 | G10: =SUMIF(WMS용마재고!$A:$A,"S309-01.25", WMS용마재고!$L:$L) -> 437 | H10: =SUMIF(WMS용마재고!$A:$A,"S309-01.50", WMS용마재고!$L:$L) -> 481 | I10: =SUMIF(WMS용마재고!$A:$A,"S309-01.75", WMS용마재고!$L:$L) -> 350 | J10: =SUMIF(WMS용마재고!$A:$A,"S309-02.00", WMS용마재고!$L:$L) -> 481 | K10: =SUMIF(WMS용마재고!$A:$A,"S309-02.25", WMS용마재고!$L:$L) -> 558 | L10: =SUMIF(WMS용마재고!$A:$A,"S309-02.50", WMS용마재고!$L:$L) -> 580 | M10: =SUMIF(WMS용마재고!$A:$A,"S309-02.75", WMS용마재고!$L:$L) -> 138 | N10: =SUMIF(WMS용마재고!$A:$A,"S309-03.00", WMS용마재고!$L:$L) -> 443 | O10: =SUMIF(WMS용마재고!$A:$A,"S309-03.25", WMS용마재고!$L:$L) -> 441 | P10: =SUMIF(WMS용마재고!$A:$A,"S309-03.50", WMS용마재고!$L:$L) -> 359 | Q10: =SUMIF(WMS용마재고!$A:$A,"S309-03.75", WMS용마재고!$L:$L) -> 382 | R10: =SUMIF(WMS용마재고!$A:$A,"S309-04.00", WMS용마재고!$L:$L) -> 509 | S10: =SUMIF(WMS용마재고!$A:$A,"S309-04.25", WMS용마재고!$L:$L) -> 0 | T10: =SUMIF(WMS용마재고!$A:$A,"S309-04.50", WMS용마재고!$L:$L) -> 387 | U10: =SUMIF(WMS용마재고!$A:$A,"S309-04.75", WMS용마재고!$L:$L) -> 380 | V10: =SUMIF(WMS용마재고!$A:$A,"S309-05.00", WMS용마재고!$L:$L) -> 496 | X10: =SUMIF(WMS용마재고!$A:$A,"S309-05.50", WMS용마재고!$L:$L) -> 475 | Z10: =SUMIF(WMS용마재고!$A:$A,"S309-06.00", WMS용마재고!$L:$L) -> 465 | AA10: =SUMIF(WMS용마재고!$A:$A,"S309-06.50", WMS용마재고!$L:$L) -> 380 | AB10: =SUMIF(WMS용마재고!$A:$A,"S309-07.00", WMS용마재고!$L:$L) -> 320 | AC10: =SUMIF(WMS용마재고!$A:$A,"S309-07.50", WMS용마재고!$L:$L) -> 0 | AD10: =SUMIF(WMS용마재고!$A:$A,"S309-08.00", WMS용마재고!$L:$L) -> 0 | AN10: O2O2 D_Ash Gray EX | AO10: =SUMIF(WMS용마재고!$A:$A,"S309-00.00", WMS용마재고!$L:$L) -> 478 | AP10: =SUMIF(WMS용마재고!$A:$A,"S309-00.50", WMS용마재고!$L:$L) -> 0 | AQ10: =SUMIF(WMS용마재고!$A:$A,"S309-00.75", WMS용마재고!$L:$L) -> 0 | AR10: =SUMIF(WMS용마재고!$A:$A,"S309-01.00", WMS용마재고!$L:$L) -> 537 | AS10: =SUMIF(WMS용마재고!$A:$A,"S309-01.25", WMS용마재고!$L:$L) -> 437 | AT10: =SUMIF(WMS용마재고!$A:$A,"S309-01.50", WMS용마재고!$L:$L) -> 481 | AU10: =SUMIF(WMS용마재고!$A:$A,"S309-01.75", WMS용마재고!$L:$L) -> 350 | AV10: =SUMIF(WMS용마재고!$A:$A,"S309-02.00", WMS용마재고!$L:$L) -> 481 | AW10: =SUMIF(WMS용마재고!$A:$A,"S309-02.25", WMS용마재고!$L:$L) -> 558 | AX10: =SUMIF(WMS용마재고!$A:$A,"S309-02.50", WMS용마재고!$L:$L) -> 580 | AY10: =SUMIF(WMS용마재고!$A:$A,"S309-02.75", WMS용마재고!$L:$L) -> 138 | AZ10: =SUMIF(WMS용마재고!$A:$A,"S309-03.00", WMS용마재고!$L:$L) -> 443 | BA10: =SUMIF(WMS용마재고!$A:$A,"S309-03.25", WMS용마재고!$L:$L) -> 441 | BB10: =SUMIF(WMS용마재고!$A:$A,"S309-03.50", WMS용마재고!$L:$L) -> 359 | BC10: =SUMIF(WMS용마재고!$A:$A,"S309-03.75", WMS용마재고!$L:$L) -> 382 | BD10: =SUMIF(WMS용마재고!$A:$A,"S309-04.00", WMS용마재고!$L:$L) -> 509 | BE10: =SUMIF(WMS용마재고!$A:$A,"S309-04.25", WMS용마재고!$L:$L) -> 0 | BF10: =SUMIF(WMS용마재고!$A:$A,"S309-04.50", WMS용마재고!$L:$L) -> 387 | BG10: =SUMIF(WMS용마재고!$A:$A,"S309-04.75", WMS용마재고!$L:$L) -> 380 | BH10: =SUMIF(WMS용마재고!$A:$A,"S309-05.00", WMS용마재고!$L:$L) -> 496 | BI10: =SUMIF(WMS용마재고!$A:$A,"S309-05.25", WMS용마재고!$L:$L) -> 0 | BJ10: =SUMIF(WMS용마재고!$A:$A,"S309-05.50", WMS용마재고!$L:$L) -> 475 | BK10: =SUMIF(WMS용마재고!$A:$A,"S309-05.75", WMS용마재고!$L:$L) -> 0 | BL10: =SUMIF(WMS용마재고!$A:$A,"S309-06.00", WMS용마재고!$L:$L) -> 465 | BM10: =SUMIF(WMS용마재고!$A:$A,"S309-06.50", WMS용마재고!$L:$L) -> 380 | BN10: =SUMIF(WMS용마재고!$A:$A,"S309-07.00", WMS용마재고!$L:$L) -> 320 | BO10: =SUMIF(WMS용마재고!$A:$A,"S309-07.50", WMS용마재고!$L:$L) -> 0 | BP10: =SUMIF(WMS용마재고!$A:$A,"S309-08.00", WMS용마재고!$L:$L) -> 0 | BQ10: =SUMIF(WMS용마재고!$A:$A,"S309-08.50", WMS용마재고!$L:$L) -> 0 | BR10: =SUMIF(WMS용마재고!$A:$A,"S309-09.00", WMS용마재고!$L:$L) -> 0 | BS10: =SUMIF(WMS용마재고!$A:$A,"S309-09.50", WMS용마재고!$L:$L) -> 0 | BT10: =SUMIF(WMS용마재고!$A:$A,"S309-10.00", WMS용마재고!$L:$L) -> 0 | BU10: =SUMIF(WMS용마재고!$A:$A,"S617-10.50", WMS용마재고!$L:$L) -> 0 | BV10: =SUMIF(WMS용마재고!$A:$A,"S617-10.50", WMS용마재고!$L:$L) -> 0 | BW10: =SUMIF(WMS용마재고!$A:$A,"S617-10.50", WMS용마재고!$L:$L) -> 0 | BX10: =SUMIF(WMS용마재고!$A:$A,"S617-10.50", WMS용마재고!$L:$L) -> 0 | BY10: 478 | BZ10: 0 | CA10: 0 | CB10: 537 | CC10: 437 | CD10: 481 | CE10: 350 | CF10: 481 | CG10: 558 | CH10: 580 | CI10: 138 | CJ10: 443 | CK10: 441 | CL10: 359 | CM10: 382 | CN10: 509 | CO10: 0 | CP10: 387 | CQ10: 380 | CR10: 496 | CS10: 0 | CT10: 475 | CU10: 0 | CV10: 465 | CW10: 380 | CX10: 320 | CY10: 0 | CZ10: 0 | DA10: 0 | DB10: 0 | DC10: 0 | DD10: 0 | DE10: 0 | DF10: 0 | DG10: 0 | DH10: 0 | DI10: =IF(AND(BY10<30, AO10>=30), "증가", "") | DJ10: =IF(AND(BZ10<30, AP10>=30), "증가", "") | DK10: =IF(AND(CA10<30, AQ10>=30), "증가", "") | DL10: =IF(AND(CB10<30, AR10>=30), "증가", "") | DM10: =IF(AND(CC10<30, AS10>=30), "증가", "") | DN10: =IF(AND(CD10<30, AT10>=30), "증가", "") | DO10: =IF(AND(CE10<30, AU10>=30), "증가", "") | DP10: =IF(AND(CF10<30, AV10>=30), "증가", "") | ... ER10: =IF(AND(DH10<30, BX10>=30), "증가", "") | ES10: =IF(AND(AO10<30, BY10>=30), "경고", "") | ET10: =IF(AND(AP10<30, BZ10>=30), "경고", "") | EU10: =IF(AND(AQ10<30, CA10>=30), "경고", "") | EV10: =IF(AND(AR10<30, CB10>=30), "경고", "") | EW10: =IF(AND(AS10<30, CC10>=30), "경고", "") | EX10: =IF(AND(AT10<30, CD10>=30), "경고", "") | EY10: =IF(AND(AU10<30, CE10>=30), "경고", "") | EZ10: =IF(AND(AV10<30, CF10>=30), "경고", "") | ... GB10: =IF(AND(BX10<30, DH10>=30), "경고", "")
A11: 8 | B11: 미셀리아 Pale Choco 10P | C11: =SUMIF(WMS용마재고!$A:$A,"S310-00.00", WMS용마재고!$L:$L) -> 351 | F11: =SUMIF(WMS용마재고!$A:$A,"S310-01.00", WMS용마재고!$L:$L) -> 223 | G11: =SUMIF(WMS용마재고!$A:$A,"S310-01.25", WMS용마재고!$L:$L) -> 240 | H11: =SUMIF(WMS용마재고!$A:$A,"S310-01.50", WMS용마재고!$L:$L) -> 257 | I11: =SUMIF(WMS용마재고!$A:$A,"S310-01.75", WMS용마재고!$L:$L) -> 320 | J11: =SUMIF(WMS용마재고!$A:$A,"S310-02.00", WMS용마재고!$L:$L) -> 410 | K11: =SUMIF(WMS용마재고!$A:$A,"S310-02.25", WMS용마재고!$L:$L) -> 197 | L11: =SUMIF(WMS용마재고!$A:$A,"S310-02.50", WMS용마재고!$L:$L) -> 284 | M11: =SUMIF(WMS용마재고!$A:$A,"S310-02.75", WMS용마재고!$L:$L) -> 288 | N11: =SUMIF(WMS용마재고!$A:$A,"S310-03.00", WMS용마재고!$L:$L) -> 260 | O11: =SUMIF(WMS용마재고!$A:$A,"S310-03.25", WMS용마재고!$L:$L) -> 269 | P11: =SUMIF(WMS용마재고!$A:$A,"S310-03.50", WMS용마재고!$L:$L) -> 262 | Q11: =SUMIF(WMS용마재고!$A:$A,"S310-03.75", WMS용마재고!$L:$L) -> 164 | R11: =SUMIF(WMS용마재고!$A:$A,"S310-04.00", WMS용마재고!$L:$L) -> 207 | S11: =SUMIF(WMS용마재고!$A:$A,"S310-04.25", WMS용마재고!$L:$L) -> 177 | T11: =SUMIF(WMS용마재고!$A:$A,"S310-04.50", WMS용마재고!$L:$L) -> 173 | U11: =SUMIF(WMS용마재고!$A:$A,"S310-04.75", WMS용마재고!$L:$L) -> 247 | V11: =SUMIF(WMS용마재고!$A:$A,"S310-05.00", WMS용마재고!$L:$L) -> 187 | X11: =SUMIF(WMS용마재고!$A:$A,"S310-05.50", WMS용마재고!$L:$L) -> 209 | Z11: =SUMIF(WMS용마재고!$A:$A,"S310-06.00", WMS용마재고!$L:$L) -> 218 | AA11: =SUMIF(WMS용마재고!$A:$A,"S310-06.50", WMS용마재고!$L:$L) -> 187 | AB11: =SUMIF(WMS용마재고!$A:$A,"S310-07.00", WMS용마재고!$L:$L) -> 166 | AC11: =SUMIF(WMS용마재고!$A:$A,"S310-07.50", WMS용마재고!$L:$L) -> 233 | AD11: =SUMIF(WMS용마재고!$A:$A,"S310-08.00", WMS용마재고!$L:$L) -> 236 | AN11: O2O2 D_Ash Gray EX | AO11: =SUMIF(WMS용마재고!$A:$A,"S310-00.00", WMS용마재고!$L:$L) -> 351 | AP11: =SUMIF(WMS용마재고!$A:$A,"S310-00.50", WMS용마재고!$L:$L) -> 0 | AQ11: =SUMIF(WMS용마재고!$A:$A,"S310-00.75", WMS용마재고!$L:$L) -> 0 | AR11: =SUMIF(WMS용마재고!$A:$A,"S310-01.00", WMS용마재고!$L:$L) -> 223 | AS11: =SUMIF(WMS용마재고!$A:$A,"S310-01.25", WMS용마재고!$L:$L) -> 240 | AT11: =SUMIF(WMS용마재고!$A:$A,"S310-01.50", WMS용마재고!$L:$L) -> 257 | AU11: =SUMIF(WMS용마재고!$A:$A,"S310-01.75", WMS용마재고!$L:$L) -> 320 | AV11: =SUMIF(WMS용마재고!$A:$A,"S310-02.00", WMS용마재고!$L:$L) -> 410 | AW11: =SUMIF(WMS용마재고!$A:$A,"S310-02.25", WMS용마재고!$L:$L) -> 197 | AX11: =SUMIF(WMS용마재고!$A:$A,"S310-02.50", WMS용마재고!$L:$L) -> 284 | AY11: =SUMIF(WMS용마재고!$A:$A,"S310-02.75", WMS용마재고!$L:$L) -> 288 | AZ11: =SUMIF(WMS용마재고!$A:$A,"S310-03.00", WMS용마재고!$L:$L) -> 260 | BA11: =SUMIF(WMS용마재고!$A:$A,"S310-03.25", WMS용마재고!$L:$L) -> 269 | BB11: =SUMIF(WMS용마재고!$A:$A,"S310-03.50", WMS용마재고!$L:$L) -> 262 | BC11: =SUMIF(WMS용마재고!$A:$A,"S310-03.75", WMS용마재고!$L:$L) -> 164 | BD11: =SUMIF(WMS용마재고!$A:$A,"S310-04.00", WMS용마재고!$L:$L) -> 207 | BE11: =SUMIF(WMS용마재고!$A:$A,"S310-04.25", WMS용마재고!$L:$L) -> 177 | BF11: =SUMIF(WMS용마재고!$A:$A,"S310-04.50", WMS용마재고!$L:$L) -> 173 | BG11: =SUMIF(WMS용마재고!$A:$A,"S310-04.75", WMS용마재고!$L:$L) -> 247 | BH11: =SUMIF(WMS용마재고!$A:$A,"S310-05.00", WMS용마재고!$L:$L) -> 187 | BI11: =SUMIF(WMS용마재고!$A:$A,"S310-05.25", WMS용마재고!$L:$L) -> 0 | BJ11: =SUMIF(WMS용마재고!$A:$A,"S310-05.50", WMS용마재고!$L:$L) -> 209 | BK11: =SUMIF(WMS용마재고!$A:$A,"S310-05.75", WMS용마재고!$L:$L) -> 0 | BL11: =SUMIF(WMS용마재고!$A:$A,"S310-06.00", WMS용마재고!$L:$L) -> 218 | BM11: =SUMIF(WMS용마재고!$A:$A,"S310-06.50", WMS용마재고!$L:$L) -> 187 | BN11: =SUMIF(WMS용마재고!$A:$A,"S310-07.00", WMS용마재고!$L:$L) -> 166 | BO11: =SUMIF(WMS용마재고!$A:$A,"S310-07.50", WMS용마재고!$L:$L) -> 233 | BP11: =SUMIF(WMS용마재고!$A:$A,"S310-08.00", WMS용마재고!$L:$L) -> 236 | BQ11: =SUMIF(WMS용마재고!$A:$A,"S310-08.50", WMS용마재고!$L:$L) -> 0 | BR11: =SUMIF(WMS용마재고!$A:$A,"S310-09.00", WMS용마재고!$L:$L) -> 0 | BS11: =SUMIF(WMS용마재고!$A:$A,"S310-09.50", WMS용마재고!$L:$L) -> 0 | BT11: =SUMIF(WMS용마재고!$A:$A,"S310-10.00", WMS용마재고!$L:$L) -> 0 | BU11: =SUMIF(WMS용마재고!$A:$A,"S617-10.50", WMS용마재고!$L:$L) -> 0 | BV11: =SUMIF(WMS용마재고!$A:$A,"S617-10.50", WMS용마재고!$L:$L) -> 0 | BW11: =SUMIF(WMS용마재고!$A:$A,"S617-10.50", WMS용마재고!$L:$L) -> 0 | BX11: =SUMIF(WMS용마재고!$A:$A,"S617-10.50", WMS용마재고!$L:$L) -> 0 | BY11: 351 | BZ11: 0 | CA11: 0 | CB11: 223 | CC11: 240 | CD11: 257 | CE11: 320 | CF11: 410 | CG11: 197 | CH11: 284 | CI11: 288 | CJ11: 260 | CK11: 269 | CL11: 262 | CM11: 164 | CN11: 207 | CO11: 177 | CP11: 173 | CQ11: 247 | CR11: 187 | CS11: 0 | CT11: 209 | CU11: 0 | CV11: 218 | CW11: 187 | CX11: 166 | CY11: 233 | CZ11: 236 | DA11: 0 | DB11: 0 | DC11: 0 | DD11: 0 | DE11: 0 | DF11: 0 | DG11: 0 | DH11: 0 | DI11: =IF(AND(BY11<30, AO11>=30), "증가", "") | DJ11: =IF(AND(BZ11<30, AP11>=30), "증가", "") | DK11: =IF(AND(CA11<30, AQ11>=30), "증가", "") | DL11: =IF(AND(CB11<30, AR11>=30), "증가", "") | DM11: =IF(AND(CC11<30, AS11>=30), "증가", "") | DN11: =IF(AND(CD11<30, AT11>=30), "증가", "") | DO11: =IF(AND(CE11<30, AU11>=30), "증가", "") | DP11: =IF(AND(CF11<30, AV11>=30), "증가", "") | ... ER11: =IF(AND(DH11<30, BX11>=30), "증가", "") | ES11: =IF(AND(AO11<30, BY11>=30), "경고", "") | ET11: =IF(AND(AP11<30, BZ11>=30), "경고", "") | EU11: =IF(AND(AQ11<30, CA11>=30), "경고", "") | EV11: =IF(AND(AR11<30, CB11>=30), "경고", "") | EW11: =IF(AND(AS11<30, CC11>=30), "경고", "") | EX11: =IF(AND(AT11<30, CD11>=30), "경고", "") | EY11: =IF(AND(AU11<30, CE11>=30), "경고", "") | EZ11: =IF(AND(AV11<30, CF11>=30), "경고", "") | ... GB11: =IF(AND(BX11<30, DH11>=30), "경고", "")
A12: * 미셀리아 2P
A13: 9 | B13: 미셀리아 Deep Black 2P | C13: =SUMIF(WMS용마재고!$A:$A,"S318-00.00", WMS용마재고!$L:$L) -> 200 | F13: =SUMIF(WMS용마재고!$A:$A,"S318-01.00", WMS용마재고!$L:$L) -> 130 | G13: =SUMIF(WMS용마재고!$A:$A,"S318-01.25", WMS용마재고!$L:$L) -> 130 | H13: =SUMIF(WMS용마재고!$A:$A,"S318-01.50", WMS용마재고!$L:$L) -> 130 | I13: =SUMIF(WMS용마재고!$A:$A,"S318-01.75", WMS용마재고!$L:$L) -> 130 | J13: =SUMIF(WMS용마재고!$A:$A,"S318-02.00", WMS용마재고!$L:$L) -> 130 | K13: =SUMIF(WMS용마재고!$A:$A,"S318-02.25", WMS용마재고!$L:$L) -> 130 | L13: =SUMIF(WMS용마재고!$A:$A,"S318-02.50", WMS용마재고!$L:$L) -> 130 | M13: =SUMIF(WMS용마재고!$A:$A,"S318-02.75", WMS용마재고!$L:$L) -> 130 | N13: =SUMIF(WMS용마재고!$A:$A,"S318-03.00", WMS용마재고!$L:$L) -> 130 | O13: =SUMIF(WMS용마재고!$A:$A,"S318-03.25", WMS용마재고!$L:$L) -> 130 | P13: =SUMIF(WMS용마재고!$A:$A,"S318-03.50", WMS용마재고!$L:$L) -> 0 | Q13: =SUMIF(WMS용마재고!$A:$A,"S318-03.75", WMS용마재고!$L:$L) -> 130 | R13: =SUMIF(WMS용마재고!$A:$A,"S318-04.00", WMS용마재고!$L:$L) -> 130 | S13: =SUMIF(WMS용마재고!$A:$A,"S318-04.25", WMS용마재고!$L:$L) -> 130 | T13: =SUMIF(WMS용마재고!$A:$A,"S318-04.50", WMS용마재고!$L:$L) -> 130 | U13: =SUMIF(WMS용마재고!$A:$A,"S318-04.75", WMS용마재고!$L:$L) -> 130 | V13: =SUMIF(WMS용마재고!$A:$A,"S318-05.00", WMS용마재고!$L:$L) -> 130 | X13: =SUMIF(WMS용마재고!$A:$A,"S318-05.50", WMS용마재고!$L:$L) -> 130 | Z13: =SUMIF(WMS용마재고!$A:$A,"S318-06.00", WMS용마재고!$L:$L) -> 130 | AA13: =SUMIF(WMS용마재고!$A:$A,"S318-06.50", WMS용마재고!$L:$L) -> 130 | AB13: =SUMIF(WMS용마재고!$A:$A,"S318-07.00", WMS용마재고!$L:$L) -> 130 | AC13: =SUMIF(WMS용마재고!$A:$A,"S318-07.50", WMS용마재고!$L:$L) -> 130 | AD13: =SUMIF(WMS용마재고!$A:$A,"S318-08.00", WMS용마재고!$L:$L) -> 130 | AN13: O2O2 D_Sepia Choco | AO13: =SUMIF(WMS용마재고!$A:$A,"S318-00.00", WMS용마재고!$L:$L) -> 200 | AP13: =SUMIF(WMS용마재고!$A:$A,"S318-00.50", WMS용마재고!$L:$L) -> 0 | AQ13: =SUMIF(WMS용마재고!$A:$A,"S318-00.75", WMS용마재고!$L:$L) -> 0 | AR13: =SUMIF(WMS용마재고!$A:$A,"S318-01.00", WMS용마재고!$L:$L) -> 130 | AS13: =SUMIF(WMS용마재고!$A:$A,"S318-01.25", WMS용마재고!$L:$L) -> 130 | AT13: =SUMIF(WMS용마재고!$A:$A,"S318-01.50", WMS용마재고!$L:$L) -> 130 | AU13: =SUMIF(WMS용마재고!$A:$A,"S318-01.75", WMS용마재고!$L:$L) -> 130 | AV13: =SUMIF(WMS용마재고!$A:$A,"S318-02.00", WMS용마재고!$L:$L) -> 130 | AW13: =SUMIF(WMS용마재고!$A:$A,"S318-02.25", WMS용마재고!$L:$L) -> 130 | AX13: =SUMIF(WMS용마재고!$A:$A,"S318-02.50", WMS용마재고!$L:$L) -> 130 | AY13: =SUMIF(WMS용마재고!$A:$A,"S318-02.75", WMS용마재고!$L:$L) -> 130 | AZ13: =SUMIF(WMS용마재고!$A:$A,"S318-03.00", WMS용마재고!$L:$L) -> 130 | BA13: =SUMIF(WMS용마재고!$A:$A,"S318-03.25", WMS용마재고!$L:$L) -> 130 | BB13: =SUMIF(WMS용마재고!$A:$A,"S318-03.50", WMS용마재고!$L:$L) -> 0 | BC13: =SUMIF(WMS용마재고!$A:$A,"S318-03.75", WMS용마재고!$L:$L) -> 130 | BD13: =SUMIF(WMS용마재고!$A:$A,"S318-04.00", WMS용마재고!$L:$L) -> 130 | BE13: =SUMIF(WMS용마재고!$A:$A,"S318-04.25", WMS용마재고!$L:$L) -> 130 | BF13: =SUMIF(WMS용마재고!$A:$A,"S318-04.50", WMS용마재고!$L:$L) -> 130 | BG13: =SUMIF(WMS용마재고!$A:$A,"S318-04.75", WMS용마재고!$L:$L) -> 130 | BH13: =SUMIF(WMS용마재고!$A:$A,"S318-05.00", WMS용마재고!$L:$L) -> 130 | BI13: =SUMIF(WMS용마재고!$A:$A,"S318-05.25", WMS용마재고!$L:$L) -> 0 | BJ13: =SUMIF(WMS용마재고!$A:$A,"S318-05.50", WMS용마재고!$L:$L) -> 130 | BK13: =SUMIF(WMS용마재고!$A:$A,"S318-05.75", WMS용마재고!$L:$L) -> 0 | BL13: =SUMIF(WMS용마재고!$A:$A,"S318-06.00", WMS용마재고!$L:$L) -> 130 | BM13: =SUMIF(WMS용마재고!$A:$A,"S318-06.50", WMS용마재고!$L:$L) -> 130 | BN13: =SUMIF(WMS용마재고!$A:$A,"S318-07.00", WMS용마재고!$L:$L) -> 130 | BO13: =SUMIF(WMS용마재고!$A:$A,"S318-07.50", WMS용마재고!$L:$L) -> 130 | BP13: =SUMIF(WMS용마재고!$A:$A,"S318-08.00", WMS용마재고!$L:$L) -> 130 | BQ13: =SUMIF(WMS용마재고!$A:$A,"S318-08.50", WMS용마재고!$L:$L) -> 0 | BR13: =SUMIF(WMS용마재고!$A:$A,"S318-09.00", WMS용마재고!$L:$L) -> 0 | BS13: =SUMIF(WMS용마재고!$A:$A,"S318-09.50", WMS용마재고!$L:$L) -> 0 | BT13: =SUMIF(WMS용마재고!$A:$A,"S318-10.00", WMS용마재고!$L:$L) -> 0 | BU13: =SUMIF(WMS용마재고!$A:$A,"s123-10.50", WMS용마재고!$L:$L) -> 0 | BV13: =SUMIF(WMS용마재고!$A:$A,"s123-10.50", WMS용마재고!$L:$L) -> 0 | BW13: =SUMIF(WMS용마재고!$A:$A,"s123-10.50", WMS용마재고!$L:$L) -> 0 | BX13: =SUMIF(WMS용마재고!$A:$A,"s123-10.50", WMS용마재고!$L:$L) -> 0 | BY13: 200 | BZ13: 0 | CA13: 0 | CB13: 130 | CC13: 130 | CD13: 130 | CE13: 130 | CF13: 130 | CG13: 130 | CH13: 130 | CI13: 130 | CJ13: 130 | CK13: 130 | CL13: 0 | CM13: 130 | CN13: 130 | CO13: 130 | CP13: 130 | CQ13: 130 | CR13: 130 | CS13: 0 | CT13: 130 | CU13: 0 | CV13: 130 | CW13: 130 | CX13: 130 | CY13: 130 | CZ13: 130 | DA13: 0 | DB13: 0 | DC13: 0 | DD13: 0 | DE13: 0 | DF13: 0 | DG13: 0 | DH13: 0 | DI13: =IF(AND(BY13<30, AO13>=30), "증가", "") | DJ13: =IF(AND(BZ13<30, AP13>=30), "증가", "") | DK13: =IF(AND(CA13<30, AQ13>=30), "증가", "") | DL13: =IF(AND(CB13<30, AR13>=30), "증가", "") | DM13: =IF(AND(CC13<30, AS13>=30), "증가", "") | DN13: =IF(AND(CD13<30, AT13>=30), "증가", "") | DO13: =IF(AND(CE13<30, AU13>=30), "증가", "") | DP13: =IF(AND(CF13<30, AV13>=30), "증가", "") | ... ER13: =IF(AND(DH13<30, BX13>=30), "증가", "") | ES13: =IF(AND(AO13<30, BY13>=30), "경고", "") | ET13: =IF(AND(AP13<30, BZ13>=30), "경고", "") | EU13: =IF(AND(AQ13<30, CA13>=30), "경고", "") | EV13: =IF(AND(AR13<30, CB13>=30), "경고", "") | EW13: =IF(AND(AS13<30, CC13>=30), "경고", "") | EX13: =IF(AND(AT13<30, CD13>=30), "경고", "") | EY13: =IF(AND(AU13<30, CE13>=30), "경고", "") | EZ13: =IF(AND(AV13<30, CF13>=30), "경고", "") | ... GB13: =IF(AND(BX13<30, DH13>=30), "경고", "")
A14: 10 | B14: 미셀리아 Lake Gray 2P | C14: =SUMIF(WMS용마재고!$A:$A,"S319-00.00", WMS용마재고!$L:$L) -> 200 | F14: =SUMIF(WMS용마재고!$A:$A,"S319-01.00", WMS용마재고!$L:$L) -> 130 | G14: =SUMIF(WMS용마재고!$A:$A,"S319-01.25", WMS용마재고!$L:$L) -> 130 | H14: =SUMIF(WMS용마재고!$A:$A,"S319-01.50", WMS용마재고!$L:$L) -> 130 | I14: =SUMIF(WMS용마재고!$A:$A,"S319-01.75", WMS용마재고!$L:$L) -> 130 | J14: =SUMIF(WMS용마재고!$A:$A,"S319-02.00", WMS용마재고!$L:$L) -> 130 | K14: =SUMIF(WMS용마재고!$A:$A,"S319-02.25", WMS용마재고!$L:$L) -> 130 | L14: =SUMIF(WMS용마재고!$A:$A,"S319-02.50", WMS용마재고!$L:$L) -> 130 | M14: =SUMIF(WMS용마재고!$A:$A,"S319-02.75", WMS용마재고!$L:$L) -> 130 | N14: =SUMIF(WMS용마재고!$A:$A,"S319-03.00", WMS용마재고!$L:$L) -> 130 | O14: =SUMIF(WMS용마재고!$A:$A,"S319-03.25", WMS용마재고!$L:$L) -> 130 | P14: =SUMIF(WMS용마재고!$A:$A,"S319-03.50", WMS용마재고!$L:$L) -> 130 | Q14: =SUMIF(WMS용마재고!$A:$A,"S319-03.75", WMS용마재고!$L:$L) -> 130 | R14: =SUMIF(WMS용마재고!$A:$A,"S319-04.00", WMS용마재고!$L:$L) -> 130 | S14: =SUMIF(WMS용마재고!$A:$A,"S319-04.25", WMS용마재고!$L:$L) -> 130 | T14: =SUMIF(WMS용마재고!$A:$A,"S319-04.50", WMS용마재고!$L:$L) -> 130 | U14: =SUMIF(WMS용마재고!$A:$A,"S319-04.75", WMS용마재고!$L:$L) -> 130 | V14: =SUMIF(WMS용마재고!$A:$A,"S319-05.00", WMS용마재고!$L:$L) -> 130 | X14: =SUMIF(WMS용마재고!$A:$A,"S319-05.50", WMS용마재고!$L:$L) -> 130 | Z14: =SUMIF(WMS용마재고!$A:$A,"S319-06.00", WMS용마재고!$L:$L) -> 130 | AA14: =SUMIF(WMS용마재고!$A:$A,"S319-06.50", WMS용마재고!$L:$L) -> 130 | AB14: =SUMIF(WMS용마재고!$A:$A,"S319-07.00", WMS용마재고!$L:$L) -> 130 | AC14: =SUMIF(WMS용마재고!$A:$A,"S319-07.50", WMS용마재고!$L:$L) -> 130 | AD14: =SUMIF(WMS용마재고!$A:$A,"S319-08.00", WMS용마재고!$L:$L) -> 130 | AN14: O2O2 D_Ash Brown EX | AO14: =SUMIF(WMS용마재고!$A:$A,"S319-00.00", WMS용마재고!$L:$L) -> 200 | AP14: =SUMIF(WMS용마재고!$A:$A,"S319-00.50", WMS용마재고!$L:$L) -> 0 | AQ14: =SUMIF(WMS용마재고!$A:$A,"S319-00.75", WMS용마재고!$L:$L) -> 0 | AR14: =SUMIF(WMS용마재고!$A:$A,"S319-01.00", WMS용마재고!$L:$L) -> 130 | AS14: =SUMIF(WMS용마재고!$A:$A,"S319-01.25", WMS용마재고!$L:$L) -> 130 | AT14: =SUMIF(WMS용마재고!$A:$A,"S319-01.50", WMS용마재고!$L:$L) -> 130 | AU14: =SUMIF(WMS용마재고!$A:$A,"S319-01.75", WMS용마재고!$L:$L) -> 130 | AV14: =SUMIF(WMS용마재고!$A:$A,"S319-02.00", WMS용마재고!$L:$L) -> 130 | AW14: =SUMIF(WMS용마재고!$A:$A,"S319-02.25", WMS용마재고!$L:$L) -> 130 | AX14: =SUMIF(WMS용마재고!$A:$A,"S319-02.50", WMS용마재고!$L:$L) -> 130 | AY14: =SUMIF(WMS용마재고!$A:$A,"S319-02.75", WMS용마재고!$L:$L) -> 130 | AZ14: =SUMIF(WMS용마재고!$A:$A,"S319-03.00", WMS용마재고!$L:$L) -> 130 | BA14: =SUMIF(WMS용마재고!$A:$A,"S319-03.25", WMS용마재고!$L:$L) -> 130 | BB14: =SUMIF(WMS용마재고!$A:$A,"S319-03.50", WMS용마재고!$L:$L) -> 130 | BC14: =SUMIF(WMS용마재고!$A:$A,"S319-03.75", WMS용마재고!$L:$L) -> 130 | BD14: =SUMIF(WMS용마재고!$A:$A,"S319-04.00", WMS용마재고!$L:$L) -> 130 | BE14: =SUMIF(WMS용마재고!$A:$A,"S319-04.25", WMS용마재고!$L:$L) -> 130 | BF14: =SUMIF(WMS용마재고!$A:$A,"S319-04.50", WMS용마재고!$L:$L) -> 130 | BG14: =SUMIF(WMS용마재고!$A:$A,"S319-04.75", WMS용마재고!$L:$L) -> 130 | BH14: =SUMIF(WMS용마재고!$A:$A,"S319-05.00", WMS용마재고!$L:$L) -> 130 | BI14: =SUMIF(WMS용마재고!$A:$A,"S319-05.25", WMS용마재고!$L:$L) -> 0 | BJ14: =SUMIF(WMS용마재고!$A:$A,"S319-05.50", WMS용마재고!$L:$L) -> 130 | BK14: =SUMIF(WMS용마재고!$A:$A,"S319-05.75", WMS용마재고!$L:$L) -> 0 | BL14: =SUMIF(WMS용마재고!$A:$A,"S319-06.00", WMS용마재고!$L:$L) -> 130 | BM14: =SUMIF(WMS용마재고!$A:$A,"S319-06.50", WMS용마재고!$L:$L) -> 130 | BN14: =SUMIF(WMS용마재고!$A:$A,"S319-07.00", WMS용마재고!$L:$L) -> 130 | BO14: =SUMIF(WMS용마재고!$A:$A,"S319-07.50", WMS용마재고!$L:$L) -> 130 | BP14: =SUMIF(WMS용마재고!$A:$A,"S319-08.00", WMS용마재고!$L:$L) -> 130 | BQ14: =SUMIF(WMS용마재고!$A:$A,"S319-08.50", WMS용마재고!$L:$L) -> 0 | BR14: =SUMIF(WMS용마재고!$A:$A,"S319-09.00", WMS용마재고!$L:$L) -> 0 | BS14: =SUMIF(WMS용마재고!$A:$A,"S319-09.50", WMS용마재고!$L:$L) -> 0 | BT14: =SUMIF(WMS용마재고!$A:$A,"S319-10.00", WMS용마재고!$L:$L) -> 0 | BV14: =SUMIF(WMS용마재고!$A:$A,"S319-10.50", WMS용마재고!$L:$L) -> 0 | BW14: =SUMIF(WMS용마재고!$A:$A,"S319-10.50", WMS용마재고!$L:$L) -> 0 | BX14: =SUMIF(WMS용마재고!$A:$A,"S319-10.50", WMS용마재고!$L:$L) -> 0 | BY14: 200 | BZ14: 0 | CA14: 0 | CB14: 130 | CC14: 130 | CD14: 130 | CE14: 130 | CF14: 130 | CG14: 130 | CH14: 130 | CI14: 130 | CJ14: 130 | CK14: 130 | CL14: 130 | CM14: 130 | CN14: 130 | CO14: 130 | CP14: 130 | CQ14: 130 | CR14: 130 | CS14: 0 | CT14: 130 | CU14: 0 | CV14: 130 | CW14: 130 | CX14: 130 | CY14: 130 | CZ14: 130 | DA14: 0 | DB14: 0 | DC14: 0 | DD14: 0 | DF14: 0 | DG14: 0 | DH14: 0 | DI14: =IF(AND(BY14<30, AO14>=30), "증가", "") | DJ14: =IF(AND(BZ14<30, AP14>=30), "증가", "") | DK14: =IF(AND(CA14<30, AQ14>=30), "증가", "") | DL14: =IF(AND(CB14<30, AR14>=30), "증가", "") | DM14: =IF(AND(CC14<30, AS14>=30), "증가", "") | DN14: =IF(AND(CD14<30, AT14>=30), "증가", "") | DO14: =IF(AND(CE14<30, AU14>=30), "증가", "") | DP14: =IF(AND(CF14<30, AV14>=30), "증가", "") | ... ER14: =IF(AND(DH14<30, BX14>=30), "증가", "") | ES14: =IF(AND(AO14<30, BY14>=30), "경고", "") | ET14: =IF(AND(AP14<30, BZ14>=30), "경고", "") | EU14: =IF(AND(AQ14<30, CA14>=30), "경고", "") | EV14: =IF(AND(AR14<30, CB14>=30), "경고", "") | EW14: =IF(AND(AS14<30, CC14>=30), "경고", "") | EX14: =IF(AND(AT14<30, CD14>=30), "경고", "") | EY14: =IF(AND(AU14<30, CE14>=30), "경고", "") | EZ14: =IF(AND(AV14<30, CF14>=30), "경고", "") | ... GB14: =IF(AND(BX14<30, DH14>=30), "경고", "")
A15: 11 | B15: 미셀리아 Mute Brown 2P | C15: =SUMIF(WMS용마재고!$A:$A,"S320-00.00", WMS용마재고!$L:$L) -> 200 | F15: =SUMIF(WMS용마재고!$A:$A,"S320-01.00", WMS용마재고!$L:$L) -> 130 | G15: =SUMIF(WMS용마재고!$A:$A,"S320-01.25", WMS용마재고!$L:$L) -> 130 | H15: =SUMIF(WMS용마재고!$A:$A,"S320-01.50", WMS용마재고!$L:$L) -> 130 | I15: =SUMIF(WMS용마재고!$A:$A,"S320-01.75", WMS용마재고!$L:$L) -> 130 | J15: =SUMIF(WMS용마재고!$A:$A,"S320-02.00", WMS용마재고!$L:$L) -> 130 | K15: =SUMIF(WMS용마재고!$A:$A,"S320-02.25", WMS용마재고!$L:$L) -> 130 | L15: =SUMIF(WMS용마재고!$A:$A,"S320-02.50", WMS용마재고!$L:$L) -> 130 | M15: =SUMIF(WMS용마재고!$A:$A,"S320-02.75", WMS용마재고!$L:$L) -> 130 | N15: =SUMIF(WMS용마재고!$A:$A,"S320-03.00", WMS용마재고!$L:$L) -> 130 | O15: =SUMIF(WMS용마재고!$A:$A,"S320-03.25", WMS용마재고!$L:$L) -> 130 | P15: =SUMIF(WMS용마재고!$A:$A,"S320-03.50", WMS용마재고!$L:$L) -> 130 | Q15: =SUMIF(WMS용마재고!$A:$A,"S320-03.75", WMS용마재고!$L:$L) -> 130 | R15: =SUMIF(WMS용마재고!$A:$A,"S320-04.00", WMS용마재고!$L:$L) -> 130 | S15: =SUMIF(WMS용마재고!$A:$A,"S320-04.25", WMS용마재고!$L:$L) -> 0 | T15: =SUMIF(WMS용마재고!$A:$A,"S320-04.50", WMS용마재고!$L:$L) -> 130 | U15: =SUMIF(WMS용마재고!$A:$A,"S320-04.75", WMS용마재고!$L:$L) -> 130 | V15: =SUMIF(WMS용마재고!$A:$A,"S320-05.00", WMS용마재고!$L:$L) -> 130 | X15: =SUMIF(WMS용마재고!$A:$A,"S320-05.50", WMS용마재고!$L:$L) -> 130 | Z15: =SUMIF(WMS용마재고!$A:$A,"S320-06.00", WMS용마재고!$L:$L) -> 130 | AA15: =SUMIF(WMS용마재고!$A:$A,"S320-06.50", WMS용마재고!$L:$L) -> 130 | AB15: =SUMIF(WMS용마재고!$A:$A,"S320-07.00", WMS용마재고!$L:$L) -> 130 | AC15: =SUMIF(WMS용마재고!$A:$A,"S320-07.50", WMS용마재고!$L:$L) -> 130 | AD15: =SUMIF(WMS용마재고!$A:$A,"S320-08.00", WMS용마재고!$L:$L) -> 130 | AN15: O2O2 D_Ash Gray EX | AO15: =SUMIF(WMS용마재고!$A:$A,"S320-00.00", WMS용마재고!$L:$L) -> 200 | AP15: =SUMIF(WMS용마재고!$A:$A,"S320-00.50", WMS용마재고!$L:$L) -> 0 | AQ15: =SUMIF(WMS용마재고!$A:$A,"S320-00.75", WMS용마재고!$L:$L) -> 0 | AR15: =SUMIF(WMS용마재고!$A:$A,"S320-01.00", WMS용마재고!$L:$L) -> 130 | AS15: =SUMIF(WMS용마재고!$A:$A,"S320-01.25", WMS용마재고!$L:$L) -> 130 | AT15: =SUMIF(WMS용마재고!$A:$A,"S320-01.50", WMS용마재고!$L:$L) -> 130 | AU15: =SUMIF(WMS용마재고!$A:$A,"S320-01.75", WMS용마재고!$L:$L) -> 130 | AV15: =SUMIF(WMS용마재고!$A:$A,"S320-02.00", WMS용마재고!$L:$L) -> 130 | AW15: =SUMIF(WMS용마재고!$A:$A,"S320-02.25", WMS용마재고!$L:$L) -> 130 | AX15: =SUMIF(WMS용마재고!$A:$A,"S320-02.50", WMS용마재고!$L:$L) -> 130 | AY15: =SUMIF(WMS용마재고!$A:$A,"S320-02.75", WMS용마재고!$L:$L) -> 130 | AZ15: =SUMIF(WMS용마재고!$A:$A,"S320-03.00", WMS용마재고!$L:$L) -> 130 | BA15: =SUMIF(WMS용마재고!$A:$A,"S320-03.25", WMS용마재고!$L:$L) -> 130 | BB15: =SUMIF(WMS용마재고!$A:$A,"S320-03.50", WMS용마재고!$L:$L) -> 130 | BC15: =SUMIF(WMS용마재고!$A:$A,"S320-03.75", WMS용마재고!$L:$L) -> 130 | BD15: =SUMIF(WMS용마재고!$A:$A,"S320-04.00", WMS용마재고!$L:$L) -> 130 | BE15: =SUMIF(WMS용마재고!$A:$A,"S320-04.25", WMS용마재고!$L:$L) -> 0 | BF15: =SUMIF(WMS용마재고!$A:$A,"S320-04.50", WMS용마재고!$L:$L) -> 130 | BG15: =SUMIF(WMS용마재고!$A:$A,"S320-04.75", WMS용마재고!$L:$L) -> 130 | BH15: =SUMIF(WMS용마재고!$A:$A,"S320-05.00", WMS용마재고!$L:$L) -> 130 | BI15: =SUMIF(WMS용마재고!$A:$A,"S320-05.25", WMS용마재고!$L:$L) -> 0 | BJ15: =SUMIF(WMS용마재고!$A:$A,"S320-05.50", WMS용마재고!$L:$L) -> 130 | BK15: =SUMIF(WMS용마재고!$A:$A,"S320-05.75", WMS용마재고!$L:$L) -> 0 | BL15: =SUMIF(WMS용마재고!$A:$A,"S320-06.00", WMS용마재고!$L:$L) -> 130 | BM15: =SUMIF(WMS용마재고!$A:$A,"S320-06.50", WMS용마재고!$L:$L) -> 130 | BN15: =SUMIF(WMS용마재고!$A:$A,"S320-07.00", WMS용마재고!$L:$L) -> 130 | BO15: =SUMIF(WMS용마재고!$A:$A,"S320-07.50", WMS용마재고!$L:$L) -> 130 | BP15: =SUMIF(WMS용마재고!$A:$A,"S320-08.00", WMS용마재고!$L:$L) -> 130 | BQ15: =SUMIF(WMS용마재고!$A:$A,"S320-08.50", WMS용마재고!$L:$L) -> 0 | BR15: =SUMIF(WMS용마재고!$A:$A,"S320-09.00", WMS용마재고!$L:$L) -> 0 | BS15: =SUMIF(WMS용마재고!$A:$A,"S320-09.50", WMS용마재고!$L:$L) -> 0 | BT15: =SUMIF(WMS용마재고!$A:$A,"S320-10.00", WMS용마재고!$L:$L) -> 0 | BU15: =SUMIF(WMS용마재고!$A:$A,"S617-10.50", WMS용마재고!$L:$L) -> 0 | BV15: =SUMIF(WMS용마재고!$A:$A,"S617-10.50", WMS용마재고!$L:$L) -> 0 | BW15: =SUMIF(WMS용마재고!$A:$A,"S617-10.50", WMS용마재고!$L:$L) -> 0 | BX15: =SUMIF(WMS용마재고!$A:$A,"S617-10.50", WMS용마재고!$L:$L) -> 0 | BY15: 200 | BZ15: 0 | CA15: 0 | CB15: 130 | CC15: 130 | CD15: 130 | CE15: 130 | CF15: 130 | CG15: 130 | CH15: 130 | CI15: 130 | CJ15: 130 | CK15: 130 | CL15: 130 | CM15: 130 | CN15: 130 | CO15: 0 | CP15: 130 | CQ15: 130 | CR15: 130 | CS15: 0 | CT15: 130 | CU15: 0 | CV15: 130 | CW15: 130 | CX15: 130 | CY15: 130 | CZ15: 130 | DA15: 0 | DB15: 0 | DC15: 0 | DD15: 0 | DE15: 0 | DF15: 0 | DG15: 0 | DH15: 0 | DI15: =IF(AND(BY15<30, AO15>=30), "증가", "") | DJ15: =IF(AND(BZ15<30, AP15>=30), "증가", "") | DK15: =IF(AND(CA15<30, AQ15>=30), "증가", "") | DL15: =IF(AND(CB15<30, AR15>=30), "증가", "") | DM15: =IF(AND(CC15<30, AS15>=30), "증가", "") | DN15: =IF(AND(CD15<30, AT15>=30), "증가", "") | DO15: =IF(AND(CE15<30, AU15>=30), "증가", "") | DP15: =IF(AND(CF15<30, AV15>=30), "증가", "") | ... ER15: =IF(AND(DH15<30, BX15>=30), "증가", "") | ES15: =IF(AND(AO15<30, BY15>=30), "경고", "") | ET15: =IF(AND(AP15<30, BZ15>=30), "경고", "") | EU15: =IF(AND(AQ15<30, CA15>=30), "경고", "") | EV15: =IF(AND(AR15<30, CB15>=30), "경고", "") | EW15: =IF(AND(AS15<30, CC15>=30), "경고", "") | EX15: =IF(AND(AT15<30, CD15>=30), "경고", "") | EY15: =IF(AND(AU15<30, CE15>=30), "경고", "") | EZ15: =IF(AND(AV15<30, CF15>=30), "경고", "") | ... GB15: =IF(AND(BX15<30, DH15>=30), "경고", "")
